<sdf version='1.6'>
  <world name='default'>
    <plugin name='welcome' filename='libwelcome_message.so'/>
    <light name='sun' type='directional'>
      <cast_shadows>1</cast_shadows>
      <pose frame=''>0 0 10 0 -0 0</pose>
      <diffuse>0.8 0.8 0.8 1</diffuse>
      <specular>0.2 0.2 0.2 1</specular>
      <attenuation>
        <range>1000</range>
        <constant>0.9</constant>
        <linear>0.01</linear>
        <quadratic>0.001</quadratic>
      </attenuation>
      <direction>-0.5 0.1 -0.9</direction>
      <spot>
        <inner_angle>0</inner_angle>
        <outer_angle>0</outer_angle>
        <falloff>0</falloff>
      </spot>
    </light>
    <model name='ground_plane'>
      <static>1</static>
      <link name='link'>
        <collision name='collision'>
          <geometry>
            <plane>
              <normal>0 0 1</normal>
              <size>100 100</size>
            </plane>
          </geometry>
          <surface>
            <contact>
              <collide_bitmask>65535</collide_bitmask>
              <ode/>
            </contact>
            <friction>
              <ode>
                <mu>100</mu>
                <mu2>50</mu2>
              </ode>
              <torsional>
                <ode/>
              </torsional>
            </friction>
            <bounce/>
          </surface>
          <max_contacts>10</max_contacts>
        </collision>
        <visual name='visual'>
          <cast_shadows>0</cast_shadows>
          <geometry>
            <plane>
              <normal>0 0 1</normal>
              <size>100 100</size>
            </plane>
          </geometry>
          <material>
            <script>
              <uri>file://media/materials/scripts/gazebo.material</uri>
              <name>Gazebo/Grey</name>
            </script>
          </material>
        </visual>
        <self_collide>0</self_collide>
        <enable_wind>0</enable_wind>
        <kinematic>0</kinematic>
      </link>
    </model>
    <gravity>0 0 -9.8</gravity>
    <magnetic_field>6e-06 2.3e-05 -4.2e-05</magnetic_field>
    <atmosphere type='adiabatic'/>
    <physics name='default_physics' default='0' type='ode'>
      <max_step_size>0.001</max_step_size>
      <real_time_factor>1</real_time_factor>
      <real_time_update_rate>1000</real_time_update_rate>
    </physics>
    <scene>
      <ambient>0.4 0.4 0.4 1</ambient>
      <background>0.7 0.7 0.7 1</background>
      <shadows>1</shadows>
    </scene>
    <audio>
      <device>default</device>
    </audio>
    <wind/>
    <spherical_coordinates>
      <surface_model>EARTH_WGS84</surface_model>
      <latitude_deg>0</latitude_deg>
      <longitude_deg>0</longitude_deg>
      <elevation>0</elevation>
      <heading_deg>0</heading_deg>
    </spherical_coordinates>
    <model name='model'>
      <pose frame=''>4.86441 3.63038 0 0 -0 0</pose>
      <link name='Wall_1'>
        <collision name='Wall_1_Collision'>
          <geometry>
            <box>
              <size>3 0.15 2.5</size>
            </box>
          </geometry>
          <pose frame=''>0 0 1.25 0 -0 0</pose>
          <max_contacts>10</max_contacts>
          <surface>
            <contact>
              <ode/>
            </contact>
            <bounce/>
            <friction>
              <torsional>
                <ode/>
              </torsional>
              <ode/>
            </friction>
          </surface>
        </collision>
        <visual name='Wall_1_Visual'>
          <pose frame=''>0 0 1.25 0 -0 0</pose>
          <geometry>
            <box>
              <size>3 0.15 2.5</size>
            </box>
          </geometry>
          <material>
            <script>
              <uri>file://media/materials/scripts/gazebo.material</uri>
              <name>Gazebo/Grey</name>
            </script>
            <ambient>1 0.764706 0.305882 1</ambient>
          </material>
          <meta>
            <layer>0</layer>
          </meta>
        </visual>
        <pose frame=''>-7.02494 2.33089 0 0 -0 0</pose>
        <self_collide>0</self_collide>
        <enable_wind>0</enable_wind>
        <kinematic>0</kinematic>
      </link>
      <link name='Wall_10'>
        <collision name='Wall_10_Collision'>
          <geometry>
            <box>
              <size>3.45374 0.15 2.5</size>
            </box>
          </geometry>
          <pose frame=''>0 0 1.25 0 -0 0</pose>
          <max_contacts>10</max_contacts>
          <surface>
            <contact>
              <ode/>
            </contact>
            <bounce/>
            <friction>
              <torsional>
                <ode/>
              </torsional>
              <ode/>
            </friction>
          </surface>
        </collision>
        <visual name='Wall_10_Visual'>
          <pose frame=''>0 0 1.25 0 -0 0</pose>
          <geometry>
            <box>
              <size>3.45374 0.15 2.5</size>
            </box>
          </geometry>
          <material>
            <script>
              <uri>file://media/materials/scripts/gazebo.material</uri>
              <name>Gazebo/Grey</name>
            </script>
            <ambient>0.996078 0.47451 0.0196078 1</ambient>
          </material>
          <meta>
            <layer>0</layer>
          </meta>
        </visual>
        <pose frame=''>2.44495 -2.70017 0 0 -0 2.58766</pose>
        <self_collide>0</self_collide>
        <enable_wind>0</enable_wind>
        <kinematic>0</kinematic>
      </link>
      <link name='Wall_11'>
        <collision name='Wall_11_Collision'>
          <geometry>
            <box>
              <size>2.25 0.15 2.5</size>
            </box>
          </geometry>
          <pose frame=''>0 0 1.25 0 -0 0</pose>
          <max_contacts>10</max_contacts>
          <surface>
            <contact>
              <ode/>
            </contact>
            <bounce/>
            <friction>
              <torsional>
                <ode/>
              </torsional>
              <ode/>
            </friction>
          </surface>
        </collision>
        <visual name='Wall_11_Visual'>
          <pose frame=''>0 0 1.25 0 -0 0</pose>
          <geometry>
            <box>
              <size>2.25 0.15 2.5</size>
            </box>
          </geometry>
          <material>
            <script>
              <uri>file://media/materials/scripts/gazebo.material</uri>
              <name>Gazebo/Grey</name>
            </script>
            <ambient>1 0.764706 0.305882 1</ambient>
          </material>
          <meta>
            <layer>0</layer>
          </meta>
        </visual>
        <pose frame=''>0.5151 -2.72911 0 0 -0 -2.0944</pose>
        <self_collide>0</self_collide>
        <enable_wind>0</enable_wind>
        <kinematic>0</kinematic>
      </link>
      <link name='Wall_2'>
        <collision name='Wall_2_Collision'>
          <geometry>
            <box>
              <size>4 0.15 2.5</size>
            </box>
          </geometry>
          <pose frame=''>0 0 1.25 0 -0 0</pose>
          <max_contacts>10</max_contacts>
          <surface>
            <contact>
              <ode/>
            </contact>
            <bounce/>
            <friction>
              <torsional>
                <ode/>
              </torsional>
              <ode/>
            </friction>
          </surface>
        </collision>
        <visual name='Wall_2_Visual'>
          <pose frame=''>0 0 1.25 0 -0 0</pose>
          <geometry>
            <box>
              <size>4 0.15 2.5</size>
            </box>
          </geometry>
          <material>
            <script>
              <uri>file://media/materials/scripts/gazebo.material</uri>
              <name>Gazebo/Grey</name>
            </script>
            <ambient>1 0.764706 0.305882 1</ambient>
          </material>
          <meta>
            <layer>0</layer>
          </meta>
        </visual>
        <pose frame=''>-4.63744 0.66379 0 0 -0 -1.0472</pose>
        <self_collide>0</self_collide>
        <enable_wind>0</enable_wind>
        <kinematic>0</kinematic>
      </link>
      <link name='Wall_20'>
        <collision name='Wall_20_Collision'>
          <geometry>
            <box>
              <size>6.98788 0.15 2.5</size>
            </box>
          </geometry>
          <pose frame=''>0 0 1.25 0 -0 0</pose>
          <max_contacts>10</max_contacts>
          <surface>
            <contact>
              <ode/>
            </contact>
            <bounce/>
            <friction>
              <torsional>
                <ode/>
              </torsional>
              <ode/>
            </friction>
          </surface>
        </collision>
        <visual name='Wall_20_Visual'>
          <pose frame=''>0 0 1.25 0 -0 0</pose>
          <geometry>
            <box>
              <size>6.98788 0.15 2.5</size>
            </box>
          </geometry>
          <material>
            <script>
              <uri>file://media/materials/scripts/gazebo.material</uri>
              <name>Gazebo/Grey</name>
            </script>
            <ambient>1 0.764706 0.305882 1</ambient>
          </material>
          <meta>
            <layer>0</layer>
          </meta>
        </visual>
        <pose frame=''>-6.75459 -0.638107 0 0 -0 -1.05196</pose>
        <self_collide>0</self_collide>
        <enable_wind>0</enable_wind>
        <kinematic>0</kinematic>
      </link>
      <link name='Wall_21'>
        <collision name='Wall_21_Collision'>
          <geometry>
            <box>
              <size>5.25 0.15 2.5</size>
            </box>
          </geometry>
          <pose frame=''>0 0 1.25 0 -0 0</pose>
          <max_contacts>10</max_contacts>
          <surface>
            <contact>
              <ode/>
            </contact>
            <bounce/>
            <friction>
              <torsional>
                <ode/>
              </torsional>
              <ode/>
            </friction>
          </surface>
        </collision>
        <visual name='Wall_21_Visual'>
          <pose frame=''>0 0 1.25 0 -0 0</pose>
          <geometry>
            <box>
              <size>5.25 0.15 2.5</size>
            </box>
          </geometry>
          <material>
            <script>
              <uri>file://media/materials/scripts/gazebo.material</uri>
              <name>Gazebo/Grey</name>
            </script>
            <ambient>1 0.764706 0.305882 1</ambient>
          </material>
          <meta>
            <layer>0</layer>
          </meta>
        </visual>
        <pose frame=''>-2.49781 -3.6071 0 0 -0 0</pose>
        <self_collide>0</self_collide>
        <enable_wind>0</enable_wind>
        <kinematic>0</kinematic>
      </link>
      <link name='Wall_23'>
        <collision name='Wall_23_Collision'>
          <geometry>
            <box>
              <size>2 0.15 2.5</size>
            </box>
          </geometry>
          <pose frame=''>0 0 1.25 0 -0 0</pose>
          <max_contacts>10</max_contacts>
          <surface>
            <contact>
              <ode/>
            </contact>
            <bounce/>
            <friction>
              <torsional>
                <ode/>
              </torsional>
              <ode/>
            </friction>
          </surface>
        </collision>
        <visual name='Wall_23_Visual'>
          <pose frame=''>0 0 1.25 0 -0 0</pose>
          <geometry>
            <box>
              <size>2 0.15 2.5</size>
            </box>
          </geometry>
          <material>
            <script>
              <uri>file://media/materials/scripts/gazebo.material</uri>
              <name>Gazebo/CeilingTiled</name>
            </script>
            <ambient>0.435294 0.796078 0.67451 1</ambient>
          </material>
          <meta>
            <layer>0</layer>
          </meta>
        </visual>
        <pose frame=''>3.37989 1.12451 0 0 -0 3.14159</pose>
        <self_collide>0</self_collide>
        <enable_wind>0</enable_wind>
        <kinematic>0</kinematic>
      </link>
      <link name='Wall_24'>
        <collision name='Wall_24_Collision'>
          <geometry>
            <box>
              <size>0.75 0.15 2.5</size>
            </box>
          </geometry>
          <pose frame=''>0 0 1.25 0 -0 0</pose>
          <max_contacts>10</max_contacts>
          <surface>
            <contact>
              <ode/>
            </contact>
            <bounce/>
            <friction>
              <torsional>
                <ode/>
              </torsional>
              <ode/>
            </friction>
          </surface>
        </collision>
        <visual name='Wall_24_Visual'>
          <pose frame=''>0 0 1.25 0 -0 0</pose>
          <geometry>
            <box>
              <size>0.75 0.15 2.5</size>
            </box>
          </geometry>
          <material>
            <script>
              <uri>file://media/materials/scripts/gazebo.material</uri>
              <name>Gazebo/CeilingTiled</name>
            </script>
            <ambient>0.435294 0.796078 0.67451 1</ambient>
          </material>
          <meta>
            <layer>0</layer>
          </meta>
        </visual>
        <pose frame=''>2.45489 0.824511 0 0 -0 -1.5708</pose>
        <self_collide>0</self_collide>
        <enable_wind>0</enable_wind>
        <kinematic>0</kinematic>
      </link>
      <link name='Wall_25'>
        <collision name='Wall_25_Collision'>
          <geometry>
            <box>
              <size>2 0.15 2.5</size>
            </box>
          </geometry>
          <pose frame=''>0 0 1.25 0 -0 0</pose>
          <max_contacts>10</max_contacts>
          <surface>
            <contact>
              <ode/>
            </contact>
            <bounce/>
            <friction>
              <torsional>
                <ode/>
              </torsional>
              <ode/>
            </friction>
          </surface>
        </collision>
        <visual name='Wall_25_Visual'>
          <pose frame=''>0 0 1.25 0 -0 0</pose>
          <geometry>
            <box>
              <size>2 0.15 2.5</size>
            </box>
          </geometry>
          <material>
            <script>
              <uri>file://media/materials/scripts/gazebo.material</uri>
              <name>Gazebo/CeilingTiled</name>
            </script>
            <ambient>0.435294 0.796078 0.67451 1</ambient>
          </material>
          <meta>
            <layer>0</layer>
          </meta>
        </visual>
        <pose frame=''>3.37989 0.524511 0 0 -0 0</pose>
        <self_collide>0</self_collide>
        <enable_wind>0</enable_wind>
        <kinematic>0</kinematic>
      </link>
      <link name='Wall_26'>
        <collision name='Wall_26_Collision'>
          <geometry>
            <box>
              <size>0.75 0.15 2.5</size>
            </box>
          </geometry>
          <pose frame=''>0 0 1.25 0 -0 0</pose>
          <max_contacts>10</max_contacts>
          <surface>
            <contact>
              <ode/>
            </contact>
            <bounce/>
            <friction>
              <torsional>
                <ode/>
              </torsional>
              <ode/>
            </friction>
          </surface>
        </collision>
        <visual name='Wall_26_Visual'>
          <pose frame=''>0 0 1.25 0 -0 0</pose>
          <geometry>
            <box>
              <size>0.75 0.15 2.5</size>
            </box>
          </geometry>
          <material>
            <script>
              <uri>file://media/materials/scripts/gazebo.material</uri>
              <name>Gazebo/CeilingTiled</name>
            </script>
            <ambient>0.435294 0.796078 0.67451 1</ambient>
          </material>
          <meta>
            <layer>0</layer>
          </meta>
        </visual>
        <pose frame=''>4.30489 0.824511 0 0 -0 1.5708</pose>
        <self_collide>0</self_collide>
        <enable_wind>0</enable_wind>
        <kinematic>0</kinematic>
      </link>
      <link name='Wall_28'>
        <collision name='Wall_28_Collision'>
          <geometry>
            <box>
              <size>0.15 0.15 2.5</size>
            </box>
          </geometry>
          <pose frame=''>0 0 1.25 0 -0 0</pose>
          <max_contacts>10</max_contacts>
          <surface>
            <contact>
              <ode/>
            </contact>
            <bounce/>
            <friction>
              <torsional>
                <ode/>
              </torsional>
              <ode/>
            </friction>
          </surface>
        </collision>
        <visual name='Wall_28_Visual'>
          <pose frame=''>0 0 1.25 0 -0 0</pose>
          <geometry>
            <box>
              <size>0.15 0.15 2.5</size>
            </box>
          </geometry>
          <material>
            <script>
              <uri>file://media/materials/scripts/gazebo.material</uri>
              <name>Gazebo/Grey</name>
            </script>
            <ambient>1 1 1 1</ambient>
          </material>
          <meta>
            <layer>0</layer>
          </meta>
        </visual>
        <pose frame=''>-3.67494 -1.00331 0 0 -0 0</pose>
        <self_collide>0</self_collide>
        <enable_wind>0</enable_wind>
        <kinematic>0</kinematic>
      </link>
      <link name='Wall_29'>
        <pose frame=''>-4.36137 -2.30521 0 0 -0 -2.05601</pose>
        <visual name='Wall_29_Visual_0'>
          <pose frame=''>-1.20446 0 1.25 0 -0 0</pose>
          <geometry>
            <box>
              <size>0.684636 0.15 2.5</size>
            </box>
          </geometry>
          <material>
            <script>
              <uri>file://media/materials/scripts/gazebo.material</uri>
              <name>Gazebo/Grey</name>
            </script>
            <ambient>1 0.764706 0.305882 1</ambient>
          </material>
          <meta>
            <layer>0</layer>
          </meta>
        </visual>
        <collision name='Wall_29_Collision_0'>
          <geometry>
            <box>
              <size>0.684636 0.15 2.5</size>
            </box>
          </geometry>
          <pose frame=''>-1.20446 0 1.25 0 -0 0</pose>
          <max_contacts>10</max_contacts>
          <surface>
            <contact>
              <ode/>
            </contact>
            <bounce/>
            <friction>
              <torsional>
                <ode/>
              </torsional>
              <ode/>
            </friction>
          </surface>
        </collision>
        <visual name='Wall_29_Visual_1'>
          <pose frame=''>1.09942 0 1.25 0 -0 0</pose>
          <geometry>
            <box>
              <size>0.894721 0.15 2.5</size>
            </box>
          </geometry>
          <material>
            <script>
              <uri>file://media/materials/scripts/gazebo.material</uri>
              <name>Gazebo/Grey</name>
            </script>
            <ambient>1 0.764706 0.305882 1</ambient>
          </material>
          <meta>
            <layer>0</layer>
          </meta>
        </visual>
        <collision name='Wall_29_Collision_1'>
          <geometry>
            <box>
              <size>0.894721 0.15 2.5</size>
            </box>
          </geometry>
          <pose frame=''>1.09942 0 1.25 0 -0 0</pose>
          <max_contacts>10</max_contacts>
          <surface>
            <contact>
              <ode/>
            </contact>
            <bounce/>
            <friction>
              <torsional>
                <ode/>
              </torsional>
              <ode/>
            </friction>
          </surface>
        </collision>
        <visual name='Wall_29_Visual_2'>
          <pose frame=''>-0.105042 0 2.25 0 -0 0</pose>
          <geometry>
            <box>
              <size>1.5142 0.15 0.5</size>
            </box>
          </geometry>
          <material>
            <script>
              <uri>file://media/materials/scripts/gazebo.material</uri>
              <name>Gazebo/Grey</name>
            </script>
            <ambient>1 0.764706 0.305882 1</ambient>
          </material>
          <meta>
            <layer>0</layer>
          </meta>
        </visual>
        <collision name='Wall_29_Collision_2'>
          <geometry>
            <box>
              <size>1.5142 0.15 0.5</size>
            </box>
          </geometry>
          <pose frame=''>-0.105042 0 2.25 0 -0 0</pose>
          <max_contacts>10</max_contacts>
          <surface>
            <contact>
              <ode/>
            </contact>
            <bounce/>
            <friction>
              <torsional>
                <ode/>
              </torsional>
              <ode/>
            </friction>
          </surface>
        </collision>
        <self_collide>0</self_collide>
        <enable_wind>0</enable_wind>
        <kinematic>0</kinematic>
      </link>
      <link name='Wall_3'>
        <collision name='Wall_3_Collision'>
          <geometry>
            <box>
              <size>1.75 0.15 2.5</size>
            </box>
          </geometry>
          <pose frame=''>0 0 1.25 0 -0 0</pose>
          <max_contacts>10</max_contacts>
          <surface>
            <contact>
              <ode/>
            </contact>
            <bounce/>
            <friction>
              <torsional>
                <ode/>
              </torsional>
              <ode/>
            </friction>
          </surface>
        </collision>
        <visual name='Wall_3_Visual'>
          <pose frame=''>0 0 1.25 0 -0 0</pose>
          <geometry>
            <box>
              <size>1.75 0.15 2.5</size>
            </box>
          </geometry>
          <material>
            <script>
              <uri>file://media/materials/scripts/gazebo.material</uri>
              <name>Gazebo/Grey</name>
            </script>
            <ambient>1 0.764706 0.305882 1</ambient>
          </material>
          <meta>
            <layer>0</layer>
          </meta>
        </visual>
        <pose frame=''>-2.87494 -1.00331 0 0 -0 0</pose>
        <self_collide>0</self_collide>
        <enable_wind>0</enable_wind>
        <kinematic>0</kinematic>
      </link>
      <link name='Wall_32'>
        <pose frame=''>-0.302239 -1.04478 0 0 -0 2.61799</pose>
        <visual name='Wall_32_Visual_0'>
          <pose frame=''>-1.15002 0 1.25 0 -0 0</pose>
          <geometry>
            <box>
              <size>0.949952 0.15 2.5</size>
            </box>
          </geometry>
          <material>
            <script>
              <uri>file://media/materials/scripts/gazebo.material</uri>
              <name>Gazebo/Grey</name>
            </script>
            <ambient>0.996078 0.47451 0.0196078 1</ambient>
          </material>
          <meta>
            <layer>0</layer>
          </meta>
        </visual>
        <collision name='Wall_32_Collision_0'>
          <geometry>
            <box>
              <size>0.949952 0.15 2.5</size>
            </box>
          </geometry>
          <pose frame=''>-1.15002 0 1.25 0 -0 0</pose>
          <max_contacts>10</max_contacts>
          <surface>
            <contact>
              <ode/>
            </contact>
            <bounce/>
            <friction>
              <torsional>
                <ode/>
              </torsional>
              <ode/>
            </friction>
          </surface>
        </collision>
        <visual name='Wall_32_Visual_1'>
          <pose frame=''>1.24923 0 1.25 0 -0 0</pose>
          <geometry>
            <box>
              <size>0.751532 0.15 2.5</size>
            </box>
          </geometry>
          <material>
            <script>
              <uri>file://media/materials/scripts/gazebo.material</uri>
              <name>Gazebo/Grey</name>
            </script>
            <ambient>0.996078 0.47451 0.0196078 1</ambient>
          </material>
          <meta>
            <layer>0</layer>
          </meta>
        </visual>
        <collision name='Wall_32_Collision_1'>
          <geometry>
            <box>
              <size>0.751532 0.15 2.5</size>
            </box>
          </geometry>
          <pose frame=''>1.24923 0 1.25 0 -0 0</pose>
          <max_contacts>10</max_contacts>
          <surface>
            <contact>
              <ode/>
            </contact>
            <bounce/>
            <friction>
              <torsional>
                <ode/>
              </torsional>
              <ode/>
            </friction>
          </surface>
        </collision>
        <visual name='Wall_32_Visual_2'>
          <pose frame=''>0.09921 0 2.25 0 -0 0</pose>
          <geometry>
            <box>
              <size>1.54852 0.15 0.5</size>
            </box>
          </geometry>
          <material>
            <script>
              <uri>file://media/materials/scripts/gazebo.material</uri>
              <name>Gazebo/Grey</name>
            </script>
            <ambient>0.996078 0.47451 0.0196078 1</ambient>
          </material>
          <meta>
            <layer>0</layer>
          </meta>
        </visual>
        <collision name='Wall_32_Collision_2'>
          <geometry>
            <box>
              <size>1.54852 0.15 0.5</size>
            </box>
          </geometry>
          <pose frame=''>0.09921 0 2.25 0 -0 0</pose>
          <max_contacts>10</max_contacts>
          <surface>
            <contact>
              <ode/>
            </contact>
            <bounce/>
            <friction>
              <torsional>
                <ode/>
              </torsional>
              <ode/>
            </friction>
          </surface>
        </collision>
        <self_collide>0</self_collide>
        <enable_wind>0</enable_wind>
        <kinematic>0</kinematic>
      </link>
      <link name='Wall_4'>
        <collision name='Wall_4_Collision'>
          <geometry>
            <box>
              <size>4 0.15 2.5</size>
            </box>
          </geometry>
          <pose frame=''>0 0 1.25 0 -0 0</pose>
          <max_contacts>10</max_contacts>
          <surface>
            <contact>
              <ode/>
            </contact>
            <bounce/>
            <friction>
              <torsional>
                <ode/>
              </torsional>
              <ode/>
            </friction>
          </surface>
        </collision>
        <visual name='Wall_4_Visual'>
          <pose frame=''>0 0 1.25 0 -0 0</pose>
          <geometry>
            <box>
              <size>4 0.15 2.5</size>
            </box>
          </geometry>
          <material>
            <script>
              <uri>file://media/materials/scripts/gazebo.material</uri>
              <name>Gazebo/Grey</name>
            </script>
            <ambient>1 0.764706 0.305882 1</ambient>
          </material>
          <meta>
            <layer>0</layer>
          </meta>
        </visual>
        <pose frame=''>-1.11244 0.66379 0 0 -0 1.0472</pose>
        <self_collide>0</self_collide>
        <enable_wind>0</enable_wind>
        <kinematic>0</kinematic>
      </link>
      <link name='Wall_5'>
        <collision name='Wall_5_Collision'>
          <geometry>
            <box>
              <size>7 0.15 2.5</size>
            </box>
          </geometry>
          <pose frame=''>0 0 1.25 0 -0 0</pose>
          <max_contacts>10</max_contacts>
          <surface>
            <contact>
              <ode/>
            </contact>
            <bounce/>
            <friction>
              <torsional>
                <ode/>
              </torsional>
              <ode/>
            </friction>
          </surface>
        </collision>
        <visual name='Wall_5_Visual'>
          <pose frame=''>0 0 1.25 0 -0 0</pose>
          <geometry>
            <box>
              <size>7 0.15 2.5</size>
            </box>
          </geometry>
          <material>
            <script>
              <uri>file://media/materials/scripts/gazebo.material</uri>
              <name>Gazebo/Grey</name>
            </script>
            <ambient>0.996078 0.47451 0.0196078 1</ambient>
          </material>
          <meta>
            <layer>0</layer>
          </meta>
        </visual>
        <pose frame=''>3.27506 2.33089 0 0 -0 0</pose>
        <self_collide>0</self_collide>
        <enable_wind>0</enable_wind>
        <kinematic>0</kinematic>
      </link>
      <link name='Wall_6'>
        <pose frame=''>6.70006 0.780889 0 0 -0 -1.5708</pose>
        <visual name='Wall_6_Visual_0'>
          <pose frame=''>-1.19377 0 1.25 0 -0 0</pose>
          <geometry>
            <box>
              <size>0.862464 0.15 2.5</size>
            </box>
          </geometry>
          <material>
            <script>
              <uri>file://media/materials/scripts/gazebo.material</uri>
              <name>Gazebo/Grey</name>
            </script>
            <ambient>0.996078 0.47451 0.0196078 1</ambient>
          </material>
          <meta>
            <layer>0</layer>
          </meta>
        </visual>
        <collision name='Wall_6_Collision_0'>
          <geometry>
            <box>
              <size>0.862464 0.15 2.5</size>
            </box>
          </geometry>
          <pose frame=''>-1.19377 0 1.25 0 -0 0</pose>
          <max_contacts>10</max_contacts>
          <surface>
            <contact>
              <ode/>
            </contact>
            <bounce/>
            <friction>
              <torsional>
                <ode/>
              </torsional>
              <ode/>
            </friction>
          </surface>
        </collision>
        <visual name='Wall_6_Visual_1'>
          <pose frame=''>1.07673 0 1.25 0 -0 0</pose>
          <geometry>
            <box>
              <size>1.09654 0.15 2.5</size>
            </box>
          </geometry>
          <material>
            <script>
              <uri>file://media/materials/scripts/gazebo.material</uri>
              <name>Gazebo/Grey</name>
            </script>
            <ambient>0.996078 0.47451 0.0196078 1</ambient>
          </material>
          <meta>
            <layer>0</layer>
          </meta>
        </visual>
        <collision name='Wall_6_Collision_1'>
          <geometry>
            <box>
              <size>1.09654 0.15 2.5</size>
            </box>
          </geometry>
          <pose frame=''>1.07673 0 1.25 0 -0 0</pose>
          <max_contacts>10</max_contacts>
          <surface>
            <contact>
              <ode/>
            </contact>
            <bounce/>
            <friction>
              <torsional>
                <ode/>
              </torsional>
              <ode/>
            </friction>
          </surface>
        </collision>
        <visual name='Wall_6_Visual_2'>
          <pose frame=''>-0.117036 0 2.25 0 -0 0</pose>
          <geometry>
            <box>
              <size>1.291 0.15 0.5</size>
            </box>
          </geometry>
          <material>
            <script>
              <uri>file://media/materials/scripts/gazebo.material</uri>
              <name>Gazebo/Grey</name>
            </script>
            <ambient>0.996078 0.47451 0.0196078 1</ambient>
          </material>
          <meta>
            <layer>0</layer>
          </meta>
        </visual>
        <collision name='Wall_6_Collision_2'>
          <geometry>
            <box>
              <size>1.291 0.15 0.5</size>
            </box>
          </geometry>
          <pose frame=''>-0.117036 0 2.25 0 -0 0</pose>
          <max_contacts>10</max_contacts>
          <surface>
            <contact>
              <ode/>
            </contact>
            <bounce/>
            <friction>
              <torsional>
                <ode/>
              </torsional>
              <ode/>
            </friction>
          </surface>
        </collision>
        <self_collide>0</self_collide>
        <enable_wind>0</enable_wind>
        <kinematic>0</kinematic>
      </link>
      <link name='Wall_7'>
        <collision name='Wall_7_Collision'>
          <geometry>
            <box>
              <size>3.25 0.15 2.5</size>
            </box>
          </geometry>
          <pose frame=''>0 0 1.25 0 -0 0</pose>
          <max_contacts>10</max_contacts>
          <surface>
            <contact>
              <ode/>
            </contact>
            <bounce/>
            <friction>
              <torsional>
                <ode/>
              </torsional>
              <ode/>
            </friction>
          </surface>
        </collision>
        <visual name='Wall_7_Visual'>
          <pose frame=''>0 0 1.25 0 -0 0</pose>
          <geometry>
            <box>
              <size>3.25 0.15 2.5</size>
            </box>
          </geometry>
          <material>
            <script>
              <uri>file://media/materials/scripts/gazebo.material</uri>
              <name>Gazebo/Grey</name>
            </script>
            <ambient>0.996078 0.47451 0.0196078 1</ambient>
          </material>
          <meta>
            <layer>0</layer>
          </meta>
        </visual>
        <pose frame=''>5.15006 -0.769112 0 0 -0 3.14159</pose>
        <self_collide>0</self_collide>
        <enable_wind>0</enable_wind>
        <kinematic>0</kinematic>
      </link>
      <link name='Wall_8'>
        <collision name='Wall_8_Collision'>
          <geometry>
            <box>
              <size>5.75 0.15 2.5</size>
            </box>
          </geometry>
          <pose frame=''>0 0 1.25 0 -0 0</pose>
          <max_contacts>10</max_contacts>
          <surface>
            <contact>
              <ode/>
            </contact>
            <bounce/>
            <friction>
              <torsional>
                <ode/>
              </torsional>
              <ode/>
            </friction>
          </surface>
        </collision>
        <visual name='Wall_8_Visual'>
          <pose frame=''>0 0 1.25 0 -0 0</pose>
          <geometry>
            <box>
              <size>5.75 0.15 2.5</size>
            </box>
          </geometry>
          <material>
            <script>
              <uri>file://media/materials/scripts/gazebo.material</uri>
              <name>Gazebo/Grey</name>
            </script>
            <ambient>0.996078 0.47451 0.0196078 1</ambient>
          </material>
          <meta>
            <layer>0</layer>
          </meta>
        </visual>
        <pose frame=''>6.02493 -2.16911 0 0 -0 -0.523599</pose>
        <self_collide>0</self_collide>
        <enable_wind>0</enable_wind>
        <kinematic>0</kinematic>
      </link>
      <link name='Wall_9'>
        <collision name='Wall_9_Collision'>
          <geometry>
            <box>
              <size>4.75 0.15 2.5</size>
            </box>
          </geometry>
          <pose frame=''>0 0 1.25 0 -0 0</pose>
          <max_contacts>10</max_contacts>
          <surface>
            <contact>
              <ode/>
            </contact>
            <bounce/>
            <friction>
              <torsional>
                <ode/>
              </torsional>
              <ode/>
            </friction>
          </surface>
        </collision>
        <visual name='Wall_9_Visual'>
          <pose frame=''>0 0 1.25 0 -0 0</pose>
          <geometry>
            <box>
              <size>4.75 0.15 2.5</size>
            </box>
          </geometry>
          <material>
            <script>
              <uri>file://media/materials/scripts/gazebo.material</uri>
              <name>Gazebo/Grey</name>
            </script>
            <ambient>0.996078 0.47451 0.0196078 1</ambient>
          </material>
          <meta>
            <layer>0</layer>
          </meta>
        </visual>
        <pose frame=''>6.1498 -3.56911 0 0 -0 3.14159</pose>
        <self_collide>0</self_collide>
        <enable_wind>0</enable_wind>
        <kinematic>0</kinematic>
      </link>
      <static>1</static>
    </model>
    <model name='model_1'>
      <model name='cart_front_steer'>
        <link name='chassis'>
          <pose frame=''>0 0 0.15 0 -0 0</pose>
          <inertial>
            <pose frame=''>0.1 0 0 0 -0 0</pose>
            <mass>10</mass>
            <inertia>
              <ixx>0.216667</ixx>
              <iyy>0.841667</iyy>
              <izz>1.04167</izz>
              <ixy>0</ixy>
              <ixz>0</ixz>
              <iyz>0</iyz>
            </inertia>
          </inertial>
          <collision name='collision'>
            <geometry>
              <box>
                <size>1 0.5 0.1</size>
              </box>
            </geometry>
            <max_contacts>10</max_contacts>
            <surface>
              <contact>
                <ode/>
              </contact>
              <bounce/>
              <friction>
                <torsional>
                  <ode/>
                </torsional>
                <ode/>
              </friction>
            </surface>
          </collision>
          <visual name='visual'>
            <geometry>
              <box>
                <size>1 0.5 0.1</size>
              </box>
            </geometry>
            <material>
              <script>
                <uri>file://media/materials/scripts/gazebo.material</uri>
                <name>Gazebo/Grey</name>
              </script>
            </material>
          </visual>
          <self_collide>0</self_collide>
          <enable_wind>0</enable_wind>
          <kinematic>0</kinematic>
        </link>
        <link name='wheel_front_left'>
          <pose frame=''>0.5 0.298 0.15 -1.5708 -0.087266 0</pose>
          <inertial>
            <mass>0.5</mass>
            <inertia>
              <ixx>0.00307917</ixx>
              <iyy>0.00307917</iyy>
              <izz>0.005625</izz>
              <ixy>0</ixy>
              <ixz>0</ixz>
              <iyz>0</iyz>
            </inertia>
            <pose frame=''>0 0 0 0 -0 0</pose>
          </inertial>
          <collision name='collision'>
            <geometry>
              <cylinder>
                <radius>0.15</radius>
                <length>0.08</length>
              </cylinder>
            </geometry>
            <max_contacts>10</max_contacts>
            <surface>
              <contact>
                <ode/>
              </contact>
              <bounce/>
              <friction>
                <torsional>
                  <ode/>
                </torsional>
                <ode/>
              </friction>
            </surface>
          </collision>
          <visual name='visual'>
            <geometry>
              <cylinder>
                <radius>0.15</radius>
                <length>0.08</length>
              </cylinder>
            </geometry>
            <material>
              <script>
                <uri>file://media/materials/scripts/gazebo.material</uri>
                <name>Gazebo/Black</name>
              </script>
            </material>
          </visual>
          <self_collide>0</self_collide>
          <enable_wind>0</enable_wind>
          <kinematic>0</kinematic>
        </link>
        <joint name='wheel_front_left_steer_spin' type='universal'>
          <parent>chassis</parent>
          <child>wheel_front_left</child>
          <axis>
            <xyz>0 -1 0</xyz>
            <limit>
              <lower>-0.610865</lower>
              <upper>0.610865</upper>
            </limit>
            <dynamics>
              <spring_reference>0</spring_reference>
              <spring_stiffness>0</spring_stiffness>
            </dynamics>
            <use_parent_model_frame>0</use_parent_model_frame>
          </axis>
          <axis2>
            <xyz>0 0 1</xyz>
            <limit>
              <upper>1e+16</upper>
              <lower>-1e+16</lower>
            </limit>
            <dynamics>
              <spring_reference>0</spring_reference>
              <spring_stiffness>0</spring_stiffness>
            </dynamics>
            <use_parent_model_frame>0</use_parent_model_frame>
          </axis2>
        </joint>
        <link name='wheel_front_right'>
          <pose frame=''>0.5 -0.298 0.15 -1.5708 -0.087266 0</pose>
          <inertial>
            <mass>0.5</mass>
            <inertia>
              <ixx>0.00307917</ixx>
              <iyy>0.00307917</iyy>
              <izz>0.005625</izz>
              <ixy>0</ixy>
              <ixz>0</ixz>
              <iyz>0</iyz>
            </inertia>
            <pose frame=''>0 0 0 0 -0 0</pose>
          </inertial>
          <collision name='collision'>
            <geometry>
              <cylinder>
                <radius>0.15</radius>
                <length>0.08</length>
              </cylinder>
            </geometry>
            <max_contacts>10</max_contacts>
            <surface>
              <contact>
                <ode/>
              </contact>
              <bounce/>
              <friction>
                <torsional>
                  <ode/>
                </torsional>
                <ode/>
              </friction>
            </surface>
          </collision>
          <visual name='visual'>
            <geometry>
              <cylinder>
                <radius>0.15</radius>
                <length>0.08</length>
              </cylinder>
            </geometry>
            <material>
              <script>
                <uri>file://media/materials/scripts/gazebo.material</uri>
                <name>Gazebo/Black</name>
              </script>
            </material>
          </visual>
          <self_collide>0</self_collide>
          <enable_wind>0</enable_wind>
          <kinematic>0</kinematic>
        </link>
        <joint name='wheel_front_right_steer_spin' type='universal'>
          <parent>chassis</parent>
          <child>wheel_front_right</child>
          <axis>
            <xyz>0 -1 0</xyz>
            <limit>
              <lower>-0.610865</lower>
              <upper>0.610865</upper>
            </limit>
            <dynamics>
              <spring_reference>0</spring_reference>
              <spring_stiffness>0</spring_stiffness>
            </dynamics>
            <use_parent_model_frame>0</use_parent_model_frame>
          </axis>
          <axis2>
            <xyz>0 0 1</xyz>
            <limit>
              <upper>1e+16</upper>
              <lower>-1e+16</lower>
            </limit>
            <dynamics>
              <spring_reference>0</spring_reference>
              <spring_stiffness>0</spring_stiffness>
            </dynamics>
            <use_parent_model_frame>0</use_parent_model_frame>
          </axis2>
        </joint>
        <link name='wheel_rear_left'>
          <pose frame=''>-0.5 0.298 0.15 -1.5708 0 0</pose>
          <inertial>
            <mass>0.5</mass>
            <inertia>
              <ixx>0.00307917</ixx>
              <iyy>0.00307917</iyy>
              <izz>0.005625</izz>
              <ixy>0</ixy>
              <ixz>0</ixz>
              <iyz>0</iyz>
            </inertia>
            <pose frame=''>0 0 0 0 -0 0</pose>
          </inertial>
          <collision name='collision'>
            <geometry>
              <cylinder>
                <radius>0.15</radius>
                <length>0.08</length>
              </cylinder>
            </geometry>
            <max_contacts>10</max_contacts>
            <surface>
              <contact>
                <ode/>
              </contact>
              <bounce/>
              <friction>
                <torsional>
                  <ode/>
                </torsional>
                <ode/>
              </friction>
            </surface>
          </collision>
          <visual name='visual'>
            <geometry>
              <cylinder>
                <radius>0.15</radius>
                <length>0.08</length>
              </cylinder>
            </geometry>
            <material>
              <script>
                <uri>file://media/materials/scripts/gazebo.material</uri>
                <name>Gazebo/Black</name>
              </script>
            </material>
          </visual>
          <self_collide>0</self_collide>
          <enable_wind>0</enable_wind>
          <kinematic>0</kinematic>
        </link>
        <joint name='wheel_rear_left_spin' type='revolute'>
          <parent>chassis</parent>
          <child>wheel_rear_left</child>
          <axis>
            <xyz>0 0 1</xyz>
            <limit>
              <lower>-1e+16</lower>
              <upper>1e+16</upper>
            </limit>
            <dynamics>
              <spring_reference>0</spring_reference>
              <spring_stiffness>0</spring_stiffness>
            </dynamics>
            <use_parent_model_frame>0</use_parent_model_frame>
          </axis>
        </joint>
        <link name='wheel_rear_right'>
          <pose frame=''>-0.5 -0.298 0.15 -1.5708 0 0</pose>
          <inertial>
            <mass>0.5</mass>
            <inertia>
              <ixx>0.00307917</ixx>
              <iyy>0.00307917</iyy>
              <izz>0.005625</izz>
              <ixy>0</ixy>
              <ixz>0</ixz>
              <iyz>0</iyz>
            </inertia>
            <pose frame=''>0 0 0 0 -0 0</pose>
          </inertial>
          <collision name='collision'>
            <geometry>
              <cylinder>
                <radius>0.15</radius>
                <length>0.08</length>
              </cylinder>
            </geometry>
            <max_contacts>10</max_contacts>
            <surface>
              <contact>
                <ode/>
              </contact>
              <bounce/>
              <friction>
                <torsional>
                  <ode/>
                </torsional>
                <ode/>
              </friction>
            </surface>
          </collision>
          <visual name='visual'>
            <geometry>
              <cylinder>
                <radius>0.15</radius>
                <length>0.08</length>
              </cylinder>
            </geometry>
            <material>
              <script>
                <uri>file://media/materials/scripts/gazebo.material</uri>
                <name>Gazebo/Black</name>
              </script>
            </material>
          </visual>
          <self_collide>0</self_collide>
          <enable_wind>0</enable_wind>
          <kinematic>0</kinematic>
        </link>
        <joint name='wheel_rear_right_spin' type='revolute'>
          <parent>chassis</parent>
          <child>wheel_rear_right</child>
          <axis>
            <xyz>0 0 1</xyz>
            <limit>
              <lower>-1e+16</lower>
              <upper>1e+16</upper>
            </limit>
            <dynamics>
              <spring_reference>0</spring_reference>
              <spring_stiffness>0</spring_stiffness>
            </dynamics>
            <use_parent_model_frame>0</use_parent_model_frame>
          </axis>
        </joint>
        <pose frame=''>-1.06061 0.576576 0 0 -0 0</pose>
      </model>
      <static>0</static>
      <allow_auto_disable>0</allow_auto_disable>
      <pose frame=''>7.27591 2.44828 0 0 -0 0</pose>
    </model>
    <state world_name='default'>
      <sim_time>668 735000000</sim_time>
      <real_time>77 282829412</real_time>
      <wall_time>1674995061 75406443</wall_time>
      <iterations>69907</iterations>
      <model name='ground_plane'>
        <pose frame=''>0 0 0 0 -0 0.3</pose>
        <scale>1 1 1</scale>
        <link name='link'>
          <pose frame=''>0 0 0 0 -0 0.3</pose>
          <velocity>0 0 0 0 -0 0</velocity>
          <acceleration>0 0 0 0 -0 0</acceleration>
          <wrench>0 0 0 0 -0 0</wrench>
        </link>
      </model>
      <model name='model'>
        <pose frame=''>4.86441 3.63038 0 0 -0 0</pose>
        <scale>1 1 1</scale>
        <link name='Wall_1'>
          <pose frame=''>-2.16053 5.96127 0 0 -0 0</pose>
          <velocity>0 0 0 0 -0 0</velocity>
          <acceleration>0 0 0 0 -0 0</acceleration>
          <wrench>0 0 0 0 -0 0</wrench>
        </link>
        <link name='Wall_10'>
          <pose frame=''>7.30936 0.93021 0 0 -0 2.58766</pose>
          <velocity>0 0 0 0 -0 0</velocity>
          <acceleration>0 0 0 0 -0 0</acceleration>
          <wrench>0 0 0 0 -0 0</wrench>
        </link>
        <link name='Wall_11'>
          <pose frame=''>5.37951 0.90127 0 0 0 -2.0944</pose>
          <velocity>0 0 0 0 -0 0</velocity>
          <acceleration>0 0 0 0 -0 0</acceleration>
          <wrench>0 0 0 0 -0 0</wrench>
        </link>
        <link name='Wall_2'>
          <pose frame=''>0.22697 4.29417 0 0 0 -1.0472</pose>
          <velocity>0 0 0 0 -0 0</velocity>
          <acceleration>0 0 0 0 -0 0</acceleration>
          <wrench>0 0 0 0 -0 0</wrench>
        </link>
        <link name='Wall_20'>
          <pose frame=''>-1.89018 2.99227 0 0 0 -1.05196</pose>
          <velocity>0 0 0 0 -0 0</velocity>
          <acceleration>0 0 0 0 -0 0</acceleration>
          <wrench>0 0 0 0 -0 0</wrench>
        </link>
        <link name='Wall_21'>
          <pose frame=''>2.3666 0.02328 0 0 -0 0</pose>
          <velocity>0 0 0 0 -0 0</velocity>
          <acceleration>0 0 0 0 -0 0</acceleration>
          <wrench>0 0 0 0 -0 0</wrench>
        </link>
        <link name='Wall_23'>
          <pose frame=''>8.2443 4.75489 0 0 -0 3.14159</pose>
          <velocity>0 0 0 0 -0 0</velocity>
          <acceleration>0 0 0 0 -0 0</acceleration>
          <wrench>0 0 0 0 -0 0</wrench>
        </link>
        <link name='Wall_24'>
          <pose frame=''>7.3193 4.45489 0 0 0 -1.5708</pose>
          <velocity>0 0 0 0 -0 0</velocity>
          <acceleration>0 0 0 0 -0 0</acceleration>
          <wrench>0 0 0 0 -0 0</wrench>
        </link>
        <link name='Wall_25'>
          <pose frame=''>8.2443 4.15489 0 0 -0 0</pose>
          <velocity>0 0 0 0 -0 0</velocity>
          <acceleration>0 0 0 0 -0 0</acceleration>
          <wrench>0 0 0 0 -0 0</wrench>
        </link>
        <link name='Wall_26'>
          <pose frame=''>9.1693 4.45489 0 0 -0 1.5708</pose>
          <velocity>0 0 0 0 -0 0</velocity>
          <acceleration>0 0 0 0 -0 0</acceleration>
          <wrench>0 0 0 0 -0 0</wrench>
        </link>
        <link name='Wall_28'>
          <pose frame=''>1.18947 2.62707 0 0 -0 0</pose>
          <velocity>0 0 0 0 -0 0</velocity>
          <acceleration>0 0 0 0 -0 0</acceleration>
          <wrench>0 0 0 0 -0 0</wrench>
        </link>
        <link name='Wall_29'>
          <pose frame=''>0.50304 1.32517 0 0 0 -2.05601</pose>
          <velocity>0 0 0 0 -0 0</velocity>
          <acceleration>0 0 0 0 -0 0</acceleration>
          <wrench>0 0 0 0 -0 0</wrench>
        </link>
        <link name='Wall_3'>
          <pose frame=''>1.98947 2.62707 0 0 -0 0</pose>
          <velocity>0 0 0 0 -0 0</velocity>
          <acceleration>0 0 0 0 -0 0</acceleration>
          <wrench>0 0 0 0 -0 0</wrench>
        </link>
        <link name='Wall_32'>
          <pose frame=''>4.56217 2.5856 0 0 -0 2.61799</pose>
          <velocity>0 0 0 0 -0 0</velocity>
          <acceleration>0 0 0 0 -0 0</acceleration>
          <wrench>0 0 0 0 -0 0</wrench>
        </link>
        <link name='Wall_4'>
          <pose frame=''>3.75197 4.29417 0 0 -0 1.0472</pose>
          <velocity>0 0 0 0 -0 0</velocity>
          <acceleration>0 0 0 0 -0 0</acceleration>
          <wrench>0 0 0 0 -0 0</wrench>
        </link>
        <link name='Wall_5'>
          <pose frame=''>8.13947 5.96127 0 0 -0 0</pose>
          <velocity>0 0 0 0 -0 0</velocity>
          <acceleration>0 0 0 0 -0 0</acceleration>
          <wrench>0 0 0 0 -0 0</wrench>
        </link>
        <link name='Wall_6'>
          <pose frame=''>11.5645 4.41127 0 0 0 -1.5708</pose>
          <velocity>0 0 0 0 -0 0</velocity>
          <acceleration>0 0 0 0 -0 0</acceleration>
          <wrench>0 0 0 0 -0 0</wrench>
        </link>
        <link name='Wall_7'>
          <pose frame=''>10.0145 2.86127 0 0 -0 3.14159</pose>
          <velocity>0 0 0 0 -0 0</velocity>
          <acceleration>0 0 0 0 -0 0</acceleration>
          <wrench>0 0 0 0 -0 0</wrench>
        </link>
        <link name='Wall_8'>
          <pose frame=''>10.8893 1.46127 0 0 0 -0.523599</pose>
          <velocity>0 0 0 0 -0 0</velocity>
          <acceleration>0 0 0 0 -0 0</acceleration>
          <wrench>0 0 0 0 -0 0</wrench>
        </link>
        <link name='Wall_9'>
          <pose frame=''>11.0142 0.06127 0 0 -0 3.14159</pose>
          <velocity>0 0 0 0 -0 0</velocity>
          <acceleration>0 0 0 0 -0 0</acceleration>
          <wrench>0 0 0 0 -0 0</wrench>
        </link>
      </model>
      <model name='model_0'>
        <pose frame=''>12.1843 3.93787 3e-06 -1e-06 -1e-06 0.008561</pose>
        <scale>1 1 1</scale>
        <model name='cart_front_steer'>
          <pose frame=''>11.1188 4.50534 2e-06 -1e-06 -1e-06 0.008561</pose>
          <scale>1 1 1</scale>
          <link name='chassis'>
            <pose frame=''>11.1188 4.50534 0.150002 -1e-06 -1e-06 0.008561</pose>
            <velocity>0.016747 -2.5e-05 0.005898 -0.01506 0 -0.000214</velocity>
            <acceleration>-0.041033 1.61029 11.4203 1.18472 -1.07151 -0.164672</acceleration>
            <wrench>-0.410327 16.1029 114.203 0 -0 0</wrench>
          </link>
          <link name='wheel_front_left'>
            <pose frame=''>11.6162 4.80761 0.150001 -1.57083 -0.438428 0.008494</pose>
            <velocity>0.016808 0.000319 0.001123 -0.002251 0.122282 -0.038362</velocity>
            <acceleration>0.013674 2.81799 -5.40894 -0.487834 -0.988874 -1.72478</acceleration>
            <wrench>0.006837 1.40899 -2.70447 0 -0 0</wrench>
          </link>
          <link name='wheel_front_right'>
            <pose frame=''>11.6213 4.21163 0.150003 -1.57062 -0.944738 0.007781</pose>
            <velocity>0.016637 -0.000148 0.010557 0.000987 0.110173 -0.015503</velocity>
            <acceleration>-0.148704 1.84622 28.3681 -0.381944 -0.555208 1.1541</acceleration>
            <wrench>-0.074352 0.923109 14.1841 0 -0 0</wrench>
          </link>
          <link name='wheel_rear_left'>
            <pose frame=''>10.6162 4.79905 0.150002 -1.57087 -1.05512 0.008625</pose>
            <velocity>0.016814 0.000584 0.001317 -0.003952 0.112131 -0.00015</velocity>
            <acceleration>0.018549 3.05193 -5.37456 -2.07953 0.008895 -0.297738</acceleration>
            <wrench>0.009274 1.52596 -2.68728 0 -0 0</wrench>
          </link>
          <link name='wheel_rear_right'>
            <pose frame=''>10.6213 4.20307 0.150001 -1.57072 -1.05551 0.008494</pose>
            <velocity>0.01668 3.4e-05 0.010668 -0.00023 0.111196 -0.00011</velocity>
            <acceleration>-0.094223 1.90976 27.9099 -1.38915 -0.590301 -0.137495</acceleration>
            <wrench>-0.047111 0.954881 13.955 0 -0 0</wrench>
          </link>
        </model>
      </model>
      <model name='model_1'>
        <pose frame=''>8.94203 2.37104 8e-06 -1.6e-05 -1e-06 0.04098</pose>
        <scale>1 1 1</scale>
        <model name='cart_front_steer'>
          <pose frame=''>7.85869 2.90368 -2e-06 -1.6e-05 -1e-06 0.04098</pose>
          <scale>1 1 1</scale>
          <link name='chassis'>
            <pose frame=''>7.85869 2.90369 0.149998 -1.6e-05 -1e-06 0.04098</pose>
            <velocity>-2.1e-05 -2e-05 -0.003911 -0.015144 -0.000465 7.7e-05</velocity>
            <acceleration>-0.001997 0.050129 -9.79367 0.217807 0.029023 -0.01446</acceleration>
            <wrench>-0.01997 0.501294 -97.9367 0 -0 0</wrench>
          </link>
          <link name='wheel_front_left'>
            <pose frame=''>8.34606 3.22192 0.149993 1.57106 1.40624 -3.10042</pose>
            <velocity>-4.7e-05 0.000254 -0.008425 -0.008214 -0.001625 0.003791</velocity>
            <acceleration>0.000183 -0.265912 -9.36733 1.57147 -0.192898 -0.75369</acceleration>
            <wrench>9.1e-05 -0.132956 -4.68367 0 -0 0</wrench>
          </link>
          <link name='wheel_front_right'>
            <pose frame=''>8.37048 2.62642 0.150003 -1.57069 -0.784731 0.040245</pose>
            <velocity>5e-06 -0.000426 0.000403 -0.023357 -0.00197 -0.01772</velocity>
            <acceleration>0.042873 -0.303389 -10.2858 0.949133 -0.975638 2.41488</acceleration>
            <wrench>0.021437 -0.151694 -5.14289 0 -0 0</wrench>
          </link>
          <link name='wheel_rear_left'>
            <pose frame=''>7.3469 3.18095 0.149993 1.57113 -1.43719 -3.10095</pose>
            <velocity>-4.6e-05 0.000187 -0.00853 -0.008858 -0.000597 0.000278</velocity>
            <acceleration>-0.005055 -0.200453 -9.83415 0.06254 -0.255057 0.013947</acceleration>
            <wrench>-0.002528 -0.100227 -4.91707 0 -0 0</wrench>
          </link>
          <link name='wheel_rear_right'>
            <pose frame=''>7.37132 2.58545 0.150001 1.57068 -1.44057 -3.1005</pose>
            <velocity>1.2e-05 -0.000393 0.000819 -0.023678 -0.000947 8.1e-05</velocity>
            <acceleration>0.001938 -0.232834 -9.83937 0.391322 -1.01446 0.083811</acceleration>
            <wrench>0.000969 -0.116417 -4.91968 0 -0 0</wrench>
          </link>
        </model>
      </model>
      <model name='my_ball'>
        <pose frame=''>-3.64155 3.54573 0.1 0 -0 0</pose>
        <scale>1 1 1</scale>
        <link name='link_0'>
          <pose frame=''>-3.64155 3.54573 0.1 0 -0 0</pose>
          <velocity>0 0 0 0 -0 0</velocity>
          <acceleration>0 0 0 0 -0 0</acceleration>
          <wrench>0 0 0 0 -0 0</wrench>
        </link>
      </model>
      <model name='ragdoll'>
        <pose frame=''>4.81268 4.42847 1.39996 1.2e-05 0.00064 -0.037719</pose>
        <scale>1 1 1</scale>
        <link name='head'>
          <pose frame=''>4.81277 4.42845 2.62496 9e-06 -0 -2e-06</pose>
          <velocity>-1e-06 -3e-05 -3.9e-05 -6.9e-05 0 0</velocity>
          <acceleration>-0.001091 -0.027215 -0.045268 -0.08376 0 -6e-06</acceleration>
          <wrench>-0.010911 -0.272145 -0.452683 0 -0 0</wrench>
        </link>
        <link name='hip'>
          <pose frame=''>4.81268 4.42847 1.39996 1.2e-05 0.00064 -0.037719</pose>
          <velocity>-6e-06 4.6e-05 -4.5e-05 0.000151 4.4e-05 -0.000166</velocity>
          <acceleration>0.004403 0.025338 -0.051697 0.132494 -0.022441 0.004043</acceleration>
          <wrench>0.044033 0.253377 -0.516971 0 -0 0</wrench>
        </link>
        <link name='l_ankle'>
          <pose frame=''>4.81257 4.64835 0.075 3.6e-05 2e-05 0.000649</pose>
          <velocity>-6e-06 6.2e-05 7e-06 -3.4e-05 -0.000136 -3.1e-05</velocity>
          <acceleration>-0.002344 0.108003 -0.007203 0.022514 -0.082862 -0.025856</acceleration>
          <wrench>-0.002344 0.108003 -0.007203 0 -0 0</wrench>
        </link>
        <link name='l_calf'>
          <pose frame=''>4.8138 4.64833 0.699998 3.6e-05 0.001969 0.000649</pose>
          <velocity>1.7e-05 7.3e-05 1e-06 -3.1e-05 3.7e-05 -2.5e-05</velocity>
          <acceleration>-0.001799 0.083946 -0.012236 0.027089 0.001172 -0.01459</acceleration>
          <wrench>-0.003597 0.167892 -0.024472 0 -0 0</wrench>
        </link>
        <link name='l_foot'>
          <pose frame=''>4.81257 4.64835 0.05 -1e-06 2.3e-05 0.000649</pose>
          <velocity>-3e-06 5.5e-05 1.9e-05 -0.001094 -5.1e-05 0</velocity>
          <acceleration>-0.000378 0.10036 0.003721 -2.00719 -0.007556 4e-05</acceleration>
          <wrench>-0.000378 0.10036 0.003721 0 -0 0</wrench>
        </link>
        <link name='l_forearm'>
          <pose frame=''>4.81335 4.75604 1.72258 -0.000202 0.001259 -0.03772</pose>
          <velocity>1e-06 -1.1e-05 -1.9e-05 2.7e-05 2e-06 -0.000167</velocity>
          <acceleration>-0.002186 -0.012645 -0.032451 0.031015 -0.00465 0.002674</acceleration>
          <wrench>-0.002186 -0.012645 -0.032451 0 -0 0</wrench>
        </link>
        <link name='l_hand'>
          <pose frame=''>4.81276 4.75597 1.24258 -0.000202 -2.9e-05 -0.037719</pose>
          <velocity>0 2e-06 -1.9e-05 2.7e-05 -1e-06 -0.000167</velocity>
          <acceleration>3.1e-05 0.002893 -0.0326 0.031275 -0.00118 0.002701</acceleration>
          <wrench>3.1e-05 0.002893 -0.0326 0 -0 0</wrench>
        </link>
        <link name='l_shoulder'>
          <pose frame=''>4.82514 4.75572 2.32246 -0.000202 -6.7e-05 -0.037719</pose>
          <velocity>5.5e-05 -3.3e-05 -2e-05 2.8e-05 -6e-06 -0.000167</velocity>
          <acceleration>-0.002279 -0.033007 -0.032738 0.032787 -0.000339 0.002738</acceleration>
          <wrench>-0.002279 -0.033007 -0.032738 0 -0 0</wrench>
        </link>
        <link name='l_thigh_lift'>
          <pose frame=''>4.82097 4.64831 1.39996 3.6e-05 0.010241 0.000649</pose>
          <velocity>3e-05 4.4e-05 -2e-06 1.3e-05 2e-05 -2.1e-05</velocity>
          <acceleration>0.003497 0.025343 -0.014888 0.063529 0.008517 -0.008688</acceleration>
          <wrench>0.017484 0.126713 -0.07444 0 -0 0</wrench>
        </link>
        <link name='l_thigh_pan'>
          <pose frame=''>4.82097 4.64831 1.39996 3.6e-05 0.000639 0.000649</pose>
          <velocity>3e-05 4.4e-05 -0 -3e-06 4.3e-05 -2e-05</velocity>
          <acceleration>0.003443 0.025323 -0.013711 0.056784 -0.022554 -0.006766</acceleration>
          <wrench>0.003443 0.025323 -0.013711 0 -0 0</wrench>
        </link>
        <link name='l_upper_arm'>
          <pose frame=''>4.82514 4.75572 2.32246 -0.000202 0.019665 -0.037723</pose>
          <velocity>5.5e-05 -3.3e-05 -2e-05 3.2e-05 9.1e-05 -0.000167</velocity>
          <acceleration>-0.002303 -0.033184 -0.032823 0.033162 0.000342 0.00274</acceleration>
          <wrench>-0.004606 -0.066367 -0.065646 0 -0 0</wrench>
        </link>
        <link name='l_wrist'>
          <pose frame=''>4.81276 4.75597 1.25758 -0.000202 4.8e-05 -0.037719</pose>
          <velocity>0 2e-06 -1.9e-05 2.7e-05 -1e-06 -0.000167</velocity>
          <acceleration>1.2e-05 0.002408 -0.032427 0.031094 -0.001287 0.002668</acceleration>
          <wrench>1.2e-05 0.002408 -0.032427 0 -0 0</wrench>
        </link>
        <link name='neck'>
          <pose frame=''>4.81279 4.42845 2.34996 9e-06 -6.7e-05 -2e-06</pose>
          <velocity>-0 -3.6e-05 -3.7e-05 -7e-05 -3e-06 0</velocity>
          <acceleration>-0.001608 -0.037494 -0.043718 -0.084803 0.003417 -6e-06</acceleration>
          <wrench>-0.001608 -0.037494 -0.043718 0 -0 0</wrench>
        </link>
        <link name='r_ankle'>
          <pose frame=''>4.81254 4.20866 0.075 3.6e-05 1e-06 -0.00086</pose>
          <velocity>-7.2e-05 1.9e-05 -0.000154 -5.5e-05 -0.000637 -0.000161</velocity>
          <acceleration>-0.061027 -0.042341 -0.157042 -0.06775 -0.492702 -0.163685</acceleration>
          <wrench>-0.061027 -0.042341 -0.157042 0 -0 0</wrench>
        </link>
        <link name='r_calf'>
          <pose frame=''>4.81215 4.20864 0.699999 3.6e-05 -0.000625 -0.00086</pose>
          <velocity>-1.2e-05 4.6e-05 -0.000124 -5.4e-05 9.7e-05 -0.000176</velocity>
          <acceleration>-0.021973 -0.00313 -0.126687 -0.069253 0.063277 -0.193067</acceleration>
          <wrench>-0.043945 -0.00626 -0.253375 0 -0 0</wrench>
        </link>
        <link name='r_foot'>
          <pose frame=''>4.81254 4.20867 0.05 0 3e-06 -0.00086</pose>
          <velocity>-5.5e-05 1.2e-05 -0.000213 0.00016 -0.001094 -0.000101</velocity>
          <acceleration>-0.048241 -0.054979 -0.12153 1.30722 -0.959214 -0.101716</acceleration>
          <wrench>-0.048241 -0.054979 -0.12153 0 -0 0</wrench>
        </link>
        <link name='r_forearm'>
          <pose frame=''>4.8121 4.10089 1.72257 0.000236 -0.001385 -0.03772</pose>
          <velocity>-1e-06 -2e-05 -6.5e-05 5.2e-05 -2e-06 -0.000167</velocity>
          <acceleration>0.002514 -0.020219 -0.066149 0.052619 0.004548 0.002984</acceleration>
          <wrench>0.002514 -0.020219 -0.066149 0 -0 0</wrench>
        </link>
        <link name='r_hand'>
          <pose frame=''>4.81275 4.10098 1.24257 0.000235 -1.1e-05 -0.037719</pose>
          <velocity>0 4e-06 -6.2e-05 5e-05 -2e-06 -0.000167</velocity>
          <acceleration>0.000327 0.004562 -0.063101 0.050365 -0.001901 0.002764</acceleration>
          <wrench>0.000327 0.004562 -0.063101 0 -0 0</wrench>
        </link>
        <link name='r_shoulder'>
          <pose frame=''>4.80044 4.10119 2.32246 0.000236 -6.7e-05 -0.037719</pose>
          <velocity>-5.5e-05 -4.8e-05 -7.1e-05 5.1e-05 -7e-06 -0.000166</velocity>
          <acceleration>-0.001029 -0.051948 -0.070662 0.051738 -0.001263 0.003278</acceleration>
          <wrench>-0.001029 -0.051948 -0.070662 0 -0 0</wrench>
        </link>
        <link name='r_thigh_lift'>
          <pose frame=''>4.80438 4.20862 1.39996 3.6e-05 -0.011097 -0.00086</pose>
          <velocity>-4.2e-05 4.6e-05 -0.000109 -2.3e-05 -3.8e-05 -0.000183</velocity>
          <acceleration>0.005341 0.023171 -0.110541 -0.054343 0.044611 -0.208323</acceleration>
          <wrench>0.026704 0.115856 -0.552706 0 -0 0</wrench>
        </link>
        <link name='r_thigh_pan'>
          <pose frame=''>4.80438 4.20862 1.39996 3.6e-05 0.000639 -0.00086</pose>
          <velocity>-4.2e-05 4.6e-05 -0.000112 -4.3e-05 4.5e-05 -0.000185</velocity>
          <acceleration>0.005293 0.022835 -0.113882 -0.075897 -0.021451 -0.212916</acceleration>
          <wrench>0.005293 0.022835 -0.113882 0 -0 0</wrench>
        </link>
        <link name='r_upper_arm'>
          <pose frame=''>4.80044 4.10119 2.32246 0.000236 -0.019436 -0.037724</pose>
          <velocity>-5.5e-05 -4.7e-05 -6.8e-05 4.8e-05 -9.2e-05 -0.000167</velocity>
          <acceleration>-0.001084 -0.051693 -0.067359 0.051467 -0.007133 0.003047</acceleration>
          <wrench>-0.002167 -0.103387 -0.134717 0 -0 0</wrench>
        </link>
        <link name='r_wrist'>
          <pose frame=''>4.81275 4.10097 1.25757 0.000236 -1.9e-05 -0.037719</pose>
          <velocity>0 3e-06 -6.4e-05 5.1e-05 -2e-06 -0.000167</velocity>
          <acceleration>0.000306 0.003823 -0.064424 0.050787 -0.001686 0.002856</acceleration>
          <wrench>0.000306 0.003823 -0.064424 0 -0 0</wrench>
        </link>
        <link name='torso'>
          <pose frame=''>4.81284 4.42846 1.64996 1.2e-05 -6.7e-05 -0.037719</pose>
          <velocity>5e-06 1e-05 -4.3e-05 8.8e-05 -8e-06 -0.000166</velocity>
          <acceleration>-0.000872 -0.005641 -0.049136 0.069405 -0.001722 0.003369</acceleration>
          <wrench>-0.026148 -0.169231 -1.47407 0 -0 0</wrench>
        </link>
      </model>
      <light name='sun'>
        <pose frame=''>0 0 10 0 -0 0</pose>
      </light>
    </state>
    <gui fullscreen='0'>
      <camera name='user_camera'>
        <pose frame=''>2.8313 -1.51327 17.7357 0 1.2818 1.50532</pose>
        <view_controller>orbit</view_controller>
        <projection_type>perspective</projection_type>
      </camera>
    </gui>
    <model name='ragdoll'>
      <pose frame=''>4.81275 4.42849 1.4 0 -0 0</pose>
      <link name='hip'>
        <inertial>
          <inertia>
            <ixx>0.1</ixx>
            <ixy>0</ixy>
            <ixz>0</ixz>
            <iyy>0.1</iyy>
            <iyz>0</iyz>
            <izz>0.1</izz>
          </inertia>
          <mass>10</mass>
          <pose frame=''>0 0 0 0 -0 0</pose>
        </inertial>
        <collision name='hip_geom'>
          <pose frame=''>0 0 0.125 0 -0 0</pose>
          <geometry>
            <box>
              <size>0.1 0.5 0.25</size>
            </box>
          </geometry>
          <surface>
            <friction>
              <ode>
                <mu>-1</mu>
                <mu2>-1</mu2>
                <fdir1>0 0 0</fdir1>
                <slip1>0</slip1>
                <slip2>0</slip2>
              </ode>
              <torsional>
                <ode/>
              </torsional>
            </friction>
            <bounce>
              <restitution_coefficient>0</restitution_coefficient>
              <threshold>100000</threshold>
            </bounce>
            <contact>
              <ode>
                <soft_cfm>0</soft_cfm>
                <soft_erp>0.2</soft_erp>
                <kp>1e+12</kp>
                <kd>1</kd>
                <max_vel>0</max_vel>
                <min_depth>0.001</min_depth>
              </ode>
            </contact>
          </surface>
          <laser_retro>0</laser_retro>
          <max_contacts>10</max_contacts>
        </collision>
        <visual name='hip_geom_visual'>
          <pose frame=''>0 0 0.125 0 -0 0</pose>
          <geometry>
            <box>
              <size>0.1 0.5 0.25</size>
            </box>
          </geometry>
          <cast_shadows>1</cast_shadows>
          <laser_retro>0</laser_retro>
          <transparency>0</transparency>
        </visual>
        <gravity>0</gravity>
        <self_collide>0</self_collide>
        <kinematic>0</kinematic>
        <enable_wind>0</enable_wind>
      </link>
      <link name='l_thigh_pan'>
        <pose frame=''>0 0.22 0 0 -0 0</pose>
        <inertial>
          <inertia>
            <ixx>0.01</ixx>
            <ixy>0</ixy>
            <ixz>0</ixz>
            <iyy>0.01</iyy>
            <iyz>0</iyz>
            <izz>0.01</izz>
          </inertia>
          <mass>1</mass>
          <pose frame=''>0 0 0 0 -0 0</pose>
        </inertial>
        <collision name='l_thigh_pan_geom'>
          <pose frame=''>0 0 -0.03 0 -0 0</pose>
          <geometry>
            <sphere>
              <radius>0.06</radius>
            </sphere>
          </geometry>
          <surface>
            <friction>
              <ode>
                <mu>-1</mu>
                <mu2>-1</mu2>
                <fdir1>0 0 0</fdir1>
                <slip1>0</slip1>
                <slip2>0</slip2>
              </ode>
              <torsional>
                <ode/>
              </torsional>
            </friction>
            <bounce>
              <restitution_coefficient>0</restitution_coefficient>
              <threshold>100000</threshold>
            </bounce>
            <contact>
              <ode>
                <soft_cfm>0</soft_cfm>
                <soft_erp>0.2</soft_erp>
                <kp>1e+12</kp>
                <kd>1</kd>
                <max_vel>0</max_vel>
                <min_depth>0.001</min_depth>
              </ode>
            </contact>
          </surface>
          <laser_retro>0</laser_retro>
          <max_contacts>10</max_contacts>
        </collision>
        <visual name='l_thigh_pan_geom_visual'>
          <pose frame=''>0 0 -0.03 0 -0 0</pose>
          <geometry>
            <sphere>
              <radius>0.06</radius>
            </sphere>
          </geometry>
          <cast_shadows>1</cast_shadows>
          <laser_retro>0</laser_retro>
          <transparency>0</transparency>
        </visual>
        <gravity>0</gravity>
        <self_collide>0</self_collide>
        <kinematic>0</kinematic>
        <enable_wind>0</enable_wind>
      </link>
      <link name='l_thigh_lift'>
        <pose frame=''>0 0.22 0 0 -0 0</pose>
        <inertial>
          <inertia>
            <ixx>0.05</ixx>
            <ixy>0</ixy>
            <ixz>0</ixz>
            <iyy>0.05</iyy>
            <iyz>0</iyz>
            <izz>0.05</izz>
          </inertia>
          <mass>5</mass>
          <pose frame=''>0 0 0 0 -0 0</pose>
        </inertial>
        <collision name='l_thigh_lift_geom'>
          <pose frame=''>0 0 -0.35 0 -0 0</pose>
          <geometry>
            <cylinder>
              <radius>0.06</radius>
              <length>0.7</length>
            </cylinder>
          </geometry>
          <surface>
            <friction>
              <ode>
                <mu>-1</mu>
                <mu2>-1</mu2>
                <fdir1>0 0 0</fdir1>
                <slip1>0</slip1>
                <slip2>0</slip2>
              </ode>
              <torsional>
                <ode/>
              </torsional>
            </friction>
            <bounce>
              <restitution_coefficient>0</restitution_coefficient>
              <threshold>100000</threshold>
            </bounce>
            <contact>
              <ode>
                <soft_cfm>0</soft_cfm>
                <soft_erp>0.2</soft_erp>
                <kp>1e+12</kp>
                <kd>1</kd>
                <max_vel>0</max_vel>
                <min_depth>0.001</min_depth>
              </ode>
            </contact>
          </surface>
          <laser_retro>0</laser_retro>
          <max_contacts>10</max_contacts>
        </collision>
        <visual name='l_thigh_lift_geom_visual'>
          <pose frame=''>0 0 -0.35 0 -0 0</pose>
          <geometry>
            <cylinder>
              <radius>0.06</radius>
              <length>0.7</length>
            </cylinder>
          </geometry>
          <cast_shadows>1</cast_shadows>
          <laser_retro>0</laser_retro>
          <transparency>0</transparency>
        </visual>
        <gravity>0</gravity>
        <self_collide>0</self_collide>
        <kinematic>0</kinematic>
        <enable_wind>0</enable_wind>
      </link>
      <link name='l_calf'>
        <pose frame=''>0 0.22 -0.7 0 -0 0</pose>
        <inertial>
          <inertia>
            <ixx>0.02</ixx>
            <ixy>0</ixy>
            <ixz>0</ixz>
            <iyy>0.02</iyy>
            <iyz>0</iyz>
            <izz>0.02</izz>
          </inertia>
          <mass>2</mass>
          <pose frame=''>0 0 0 0 -0 0</pose>
        </inertial>
        <collision name='l_calf_geom'>
          <pose frame=''>0 0 -0.3 0 -0 0</pose>
          <geometry>
            <cylinder>
              <radius>0.05</radius>
              <length>0.6</length>
            </cylinder>
          </geometry>
          <surface>
            <friction>
              <ode>
                <mu>-1</mu>
                <mu2>-1</mu2>
                <fdir1>0 0 0</fdir1>
                <slip1>0</slip1>
                <slip2>0</slip2>
              </ode>
              <torsional>
                <ode/>
              </torsional>
            </friction>
            <bounce>
              <restitution_coefficient>0</restitution_coefficient>
              <threshold>100000</threshold>
            </bounce>
            <contact>
              <ode>
                <soft_cfm>0</soft_cfm>
                <soft_erp>0.2</soft_erp>
                <kp>1e+12</kp>
                <kd>1</kd>
                <max_vel>0</max_vel>
                <min_depth>0.001</min_depth>
              </ode>
            </contact>
          </surface>
          <laser_retro>0</laser_retro>
          <max_contacts>10</max_contacts>
        </collision>
        <visual name='l_calf_geom_visual'>
          <pose frame=''>0 0 -0.3 0 -0 0</pose>
          <geometry>
            <cylinder>
              <radius>0.05</radius>
              <length>0.6</length>
            </cylinder>
          </geometry>
          <cast_shadows>1</cast_shadows>
          <laser_retro>0</laser_retro>
          <transparency>0</transparency>
        </visual>
        <gravity>0</gravity>
        <self_collide>0</self_collide>
        <kinematic>0</kinematic>
        <enable_wind>0</enable_wind>
      </link>
      <link name='l_ankle'>
        <pose frame=''>0 0.22 -1.325 0 -0 0</pose>
        <inertial>
          <inertia>
            <ixx>0.01</ixx>
            <ixy>0</ixy>
            <ixz>0</ixz>
            <iyy>0.01</iyy>
            <iyz>0</iyz>
            <izz>0.01</izz>
          </inertia>
          <mass>1</mass>
          <pose frame=''>0 0 0 0 -0 0</pose>
        </inertial>
        <collision name='l_ankle_geom'>
          <geometry>
            <sphere>
              <radius>0.05</radius>
            </sphere>
          </geometry>
          <surface>
            <friction>
              <ode>
                <mu>-1</mu>
                <mu2>-1</mu2>
                <fdir1>0 0 0</fdir1>
                <slip1>0</slip1>
                <slip2>0</slip2>
              </ode>
              <torsional>
                <ode/>
              </torsional>
            </friction>
            <bounce>
              <restitution_coefficient>0</restitution_coefficient>
              <threshold>100000</threshold>
            </bounce>
            <contact>
              <ode>
                <soft_cfm>0</soft_cfm>
                <soft_erp>0.2</soft_erp>
                <kp>1e+12</kp>
                <kd>1</kd>
                <max_vel>0</max_vel>
                <min_depth>0.001</min_depth>
              </ode>
            </contact>
          </surface>
          <laser_retro>0</laser_retro>
          <max_contacts>10</max_contacts>
        </collision>
        <visual name='l_ankle_geom_visual'>
          <geometry>
            <sphere>
              <radius>0.05</radius>
            </sphere>
          </geometry>
          <cast_shadows>1</cast_shadows>
          <laser_retro>0</laser_retro>
          <transparency>0</transparency>
        </visual>
        <gravity>0</gravity>
        <self_collide>0</self_collide>
        <kinematic>0</kinematic>
        <enable_wind>0</enable_wind>
      </link>
      <link name='l_foot'>
        <pose frame=''>0 0.22 -1.35 0 -0 0</pose>
        <inertial>
          <pose frame=''>0.1 0 0 0 -0 0</pose>
          <inertia>
            <ixx>0.01</ixx>
            <ixy>0</ixy>
            <ixz>0</ixz>
            <iyy>0.01</iyy>
            <iyz>0</iyz>
            <izz>0.01</izz>
          </inertia>
          <mass>1</mass>
        </inertial>
        <collision name='l_foot_geom'>
          <pose frame=''>0.1 0 -0.025 0 -0 0</pose>
          <geometry>
            <box>
              <size>0.2 0.03 0.05</size>
            </box>
          </geometry>
          <surface>
            <friction>
              <ode>
                <mu>-1</mu>
                <mu2>-1</mu2>
                <fdir1>0 0 0</fdir1>
                <slip1>0</slip1>
                <slip2>0</slip2>
              </ode>
              <torsional>
                <ode/>
              </torsional>
            </friction>
            <bounce>
              <restitution_coefficient>0</restitution_coefficient>
              <threshold>100000</threshold>
            </bounce>
            <contact>
              <ode>
                <soft_cfm>0</soft_cfm>
                <soft_erp>0.2</soft_erp>
                <kp>1e+12</kp>
                <kd>1</kd>
                <max_vel>0</max_vel>
                <min_depth>0.001</min_depth>
              </ode>
            </contact>
          </surface>
          <laser_retro>0</laser_retro>
          <max_contacts>10</max_contacts>
        </collision>
        <visual name='l_foot_geom_visual'>
          <pose frame=''>0.1 0 -0.025 0 -0 0</pose>
          <geometry>
            <box>
              <size>0.2 0.03 0.05</size>
            </box>
          </geometry>
          <cast_shadows>1</cast_shadows>
          <laser_retro>0</laser_retro>
          <transparency>0</transparency>
        </visual>
        <gravity>1</gravity>
        <self_collide>0</self_collide>
        <kinematic>0</kinematic>
        <enable_wind>0</enable_wind>
      </link>
      <link name='r_thigh_pan'>
        <pose frame=''>0 -0.22 0 0 -0 0</pose>
        <inertial>
          <inertia>
            <ixx>0.01</ixx>
            <ixy>0</ixy>
            <ixz>0</ixz>
            <iyy>0.01</iyy>
            <iyz>0</iyz>
            <izz>0.01</izz>
          </inertia>
          <mass>1</mass>
          <pose frame=''>0 0 0 0 -0 0</pose>
        </inertial>
        <collision name='r_thigh_pan_geom'>
          <pose frame=''>0 0 -0.03 0 -0 0</pose>
          <geometry>
            <sphere>
              <radius>0.06</radius>
            </sphere>
          </geometry>
          <surface>
            <friction>
              <ode>
                <mu>-1</mu>
                <mu2>-1</mu2>
                <fdir1>0 0 0</fdir1>
                <slip1>0</slip1>
                <slip2>0</slip2>
              </ode>
              <torsional>
                <ode/>
              </torsional>
            </friction>
            <bounce>
              <restitution_coefficient>0</restitution_coefficient>
              <threshold>100000</threshold>
            </bounce>
            <contact>
              <ode>
                <soft_cfm>0</soft_cfm>
                <soft_erp>0.2</soft_erp>
                <kp>1e+12</kp>
                <kd>1</kd>
                <max_vel>0</max_vel>
                <min_depth>0.001</min_depth>
              </ode>
            </contact>
          </surface>
          <laser_retro>0</laser_retro>
          <max_contacts>10</max_contacts>
        </collision>
        <visual name='r_thigh_pan_geom_visual'>
          <pose frame=''>0 0 -0.03 0 -0 0</pose>
          <geometry>
            <sphere>
              <radius>0.06</radius>
            </sphere>
          </geometry>
          <cast_shadows>1</cast_shadows>
          <laser_retro>0</laser_retro>
          <transparency>0</transparency>
        </visual>
        <gravity>0</gravity>
        <self_collide>0</self_collide>
        <kinematic>0</kinematic>
        <enable_wind>0</enable_wind>
      </link>
      <link name='r_thigh_lift'>
        <pose frame=''>0 -0.22 0 0 -0 0</pose>
        <inertial>
          <inertia>
            <ixx>0.05</ixx>
            <ixy>0</ixy>
            <ixz>0</ixz>
            <iyy>0.05</iyy>
            <iyz>0</iyz>
            <izz>0.05</izz>
          </inertia>
          <mass>5</mass>
          <pose frame=''>0 0 0 0 -0 0</pose>
        </inertial>
        <collision name='r_thigh_lift_geom'>
          <pose frame=''>0 0 -0.35 0 -0 0</pose>
          <geometry>
            <cylinder>
              <radius>0.06</radius>
              <length>0.7</length>
            </cylinder>
          </geometry>
          <surface>
            <friction>
              <ode>
                <mu>-1</mu>
                <mu2>-1</mu2>
                <fdir1>0 0 0</fdir1>
                <slip1>0</slip1>
                <slip2>0</slip2>
              </ode>
              <torsional>
                <ode/>
              </torsional>
            </friction>
            <bounce>
              <restitution_coefficient>0</restitution_coefficient>
              <threshold>100000</threshold>
            </bounce>
            <contact>
              <ode>
                <soft_cfm>0</soft_cfm>
                <soft_erp>0.2</soft_erp>
                <kp>1e+12</kp>
                <kd>1</kd>
                <max_vel>0</max_vel>
                <min_depth>0.001</min_depth>
              </ode>
            </contact>
          </surface>
          <laser_retro>0</laser_retro>
          <max_contacts>10</max_contacts>
        </collision>
        <visual name='r_thigh_lift_geom_visual'>
          <pose frame=''>0 0 -0.35 0 -0 0</pose>
          <geometry>
            <cylinder>
              <radius>0.06</radius>
              <length>0.7</length>
            </cylinder>
          </geometry>
          <cast_shadows>1</cast_shadows>
          <laser_retro>0</laser_retro>
          <transparency>0</transparency>
        </visual>
        <gravity>0</gravity>
        <self_collide>0</self_collide>
        <kinematic>0</kinematic>
        <enable_wind>0</enable_wind>
      </link>
      <link name='r_calf'>
        <pose frame=''>0 -0.22 -0.7 0 -0 0</pose>
        <inertial>
          <inertia>
            <ixx>0.02</ixx>
            <ixy>0</ixy>
            <ixz>0</ixz>
            <iyy>0.02</iyy>
            <iyz>0</iyz>
            <izz>0.02</izz>
          </inertia>
          <mass>2</mass>
          <pose frame=''>0 0 0 0 -0 0</pose>
        </inertial>
        <collision name='r_calf_geom'>
          <pose frame=''>0 0 -0.3 0 -0 0</pose>
          <geometry>
            <cylinder>
              <radius>0.05</radius>
              <length>0.6</length>
            </cylinder>
          </geometry>
          <surface>
            <friction>
              <ode>
                <mu>-1</mu>
                <mu2>-1</mu2>
                <fdir1>0 0 0</fdir1>
                <slip1>0</slip1>
                <slip2>0</slip2>
              </ode>
              <torsional>
                <ode/>
              </torsional>
            </friction>
            <bounce>
              <restitution_coefficient>0</restitution_coefficient>
              <threshold>100000</threshold>
            </bounce>
            <contact>
              <ode>
                <soft_cfm>0</soft_cfm>
                <soft_erp>0.2</soft_erp>
                <kp>1e+12</kp>
                <kd>1</kd>
                <max_vel>0</max_vel>
                <min_depth>0.001</min_depth>
              </ode>
            </contact>
          </surface>
          <laser_retro>0</laser_retro>
          <max_contacts>10</max_contacts>
        </collision>
        <visual name='r_calf_geom_visual'>
          <pose frame=''>0 0 -0.3 0 -0 0</pose>
          <geometry>
            <cylinder>
              <radius>0.05</radius>
              <length>0.6</length>
            </cylinder>
          </geometry>
          <cast_shadows>1</cast_shadows>
          <laser_retro>0</laser_retro>
          <transparency>0</transparency>
        </visual>
        <gravity>0</gravity>
        <self_collide>0</self_collide>
        <kinematic>0</kinematic>
        <enable_wind>0</enable_wind>
      </link>
      <link name='r_ankle'>
        <pose frame=''>0 -0.22 -1.325 0 -0 0</pose>
        <inertial>
          <inertia>
            <ixx>0.01</ixx>
            <ixy>0</ixy>
            <ixz>0</ixz>
            <iyy>0.01</iyy>
            <iyz>0</iyz>
            <izz>0.01</izz>
          </inertia>
          <mass>1</mass>
          <pose frame=''>0 0 0 0 -0 0</pose>
        </inertial>
        <collision name='r_ankle_geom'>
          <geometry>
            <sphere>
              <radius>0.05</radius>
            </sphere>
          </geometry>
          <surface>
            <friction>
              <ode>
                <mu>-1</mu>
                <mu2>-1</mu2>
                <fdir1>0 0 0</fdir1>
                <slip1>0</slip1>
                <slip2>0</slip2>
              </ode>
              <torsional>
                <ode/>
              </torsional>
            </friction>
            <bounce>
              <restitution_coefficient>0</restitution_coefficient>
              <threshold>100000</threshold>
            </bounce>
            <contact>
              <ode>
                <soft_cfm>0</soft_cfm>
                <soft_erp>0.2</soft_erp>
                <kp>1e+12</kp>
                <kd>1</kd>
                <max_vel>0</max_vel>
                <min_depth>0.001</min_depth>
              </ode>
            </contact>
          </surface>
          <laser_retro>0</laser_retro>
          <max_contacts>10</max_contacts>
        </collision>
        <visual name='r_ankle_geom_visual'>
          <geometry>
            <sphere>
              <radius>0.05</radius>
            </sphere>
          </geometry>
          <cast_shadows>1</cast_shadows>
          <laser_retro>0</laser_retro>
          <transparency>0</transparency>
        </visual>
        <gravity>0</gravity>
        <self_collide>0</self_collide>
        <kinematic>0</kinematic>
        <enable_wind>0</enable_wind>
      </link>
      <link name='r_foot'>
        <pose frame=''>0 -0.22 -1.35 0 -0 0</pose>
        <inertial>
          <pose frame=''>0.1 0 0 0 -0 0</pose>
          <inertia>
            <ixx>0.01</ixx>
            <ixy>0</ixy>
            <ixz>0</ixz>
            <iyy>0.01</iyy>
            <iyz>0</iyz>
            <izz>0.01</izz>
          </inertia>
          <mass>1</mass>
        </inertial>
        <collision name='r_foot_geom'>
          <pose frame=''>0.1 0 -0.025 0 -0 0</pose>
          <geometry>
            <box>
              <size>0.2 0.03 0.05</size>
            </box>
          </geometry>
          <surface>
            <friction>
              <ode>
                <mu>-1</mu>
                <mu2>-1</mu2>
                <fdir1>0 0 0</fdir1>
                <slip1>0</slip1>
                <slip2>0</slip2>
              </ode>
              <torsional>
                <ode/>
              </torsional>
            </friction>
            <bounce>
              <restitution_coefficient>0</restitution_coefficient>
              <threshold>100000</threshold>
            </bounce>
            <contact>
              <ode>
                <soft_cfm>0</soft_cfm>
                <soft_erp>0.2</soft_erp>
                <kp>1e+12</kp>
                <kd>1</kd>
                <max_vel>0</max_vel>
                <min_depth>0.001</min_depth>
              </ode>
            </contact>
          </surface>
          <laser_retro>0</laser_retro>
          <max_contacts>10</max_contacts>
        </collision>
        <visual name='r_foot_geom_visual'>
          <pose frame=''>0.1 0 -0.025 0 -0 0</pose>
          <geometry>
            <box>
              <size>0.2 0.03 0.05</size>
            </box>
          </geometry>
          <cast_shadows>1</cast_shadows>
          <laser_retro>0</laser_retro>
          <transparency>0</transparency>
        </visual>
        <gravity>1</gravity>
        <self_collide>0</self_collide>
        <kinematic>0</kinematic>
        <enable_wind>0</enable_wind>
      </link>
      <link name='torso'>
        <pose frame=''>0 0 0.25 0 -0 0</pose>
        <inertial>
          <inertia>
            <ixx>0.3</ixx>
            <ixy>0</ixy>
            <ixz>0</ixz>
            <iyy>0.3</iyy>
            <iyz>0</iyz>
            <izz>0.3</izz>
          </inertia>
          <mass>30</mass>
          <pose frame=''>0 0 0 0 -0 0</pose>
        </inertial>
        <collision name='torso_geom'>
          <pose frame=''>0 0 0.35 0 -0 0</pose>
          <geometry>
            <box>
              <size>0.1 0.6 0.7</size>
            </box>
          </geometry>
          <surface>
            <friction>
              <ode>
                <mu>-1</mu>
                <mu2>-1</mu2>
                <fdir1>0 0 0</fdir1>
                <slip1>0</slip1>
                <slip2>0</slip2>
              </ode>
              <torsional>
                <ode/>
              </torsional>
            </friction>
            <bounce>
              <restitution_coefficient>0</restitution_coefficient>
              <threshold>100000</threshold>
            </bounce>
            <contact>
              <ode>
                <soft_cfm>0</soft_cfm>
                <soft_erp>0.2</soft_erp>
                <kp>1e+12</kp>
                <kd>1</kd>
                <max_vel>0</max_vel>
                <min_depth>0.001</min_depth>
              </ode>
            </contact>
          </surface>
          <laser_retro>0</laser_retro>
          <max_contacts>10</max_contacts>
        </collision>
        <visual name='torso_geom_visual'>
          <pose frame=''>0 0 0.35 0 -0 0</pose>
          <geometry>
            <box>
              <size>0.1 0.6 0.7</size>
            </box>
          </geometry>
          <cast_shadows>1</cast_shadows>
          <laser_retro>0</laser_retro>
          <transparency>0</transparency>
        </visual>
        <gravity>0</gravity>
        <self_collide>0</self_collide>
        <kinematic>0</kinematic>
        <enable_wind>0</enable_wind>
      </link>
      <link name='l_shoulder'>
        <pose frame=''>0 0.3275 0.9225 0 -0 0</pose>
        <inertial>
          <inertia>
            <ixx>0.01</ixx>
            <ixy>0</ixy>
            <ixz>0</ixz>
            <iyy>0.01</iyy>
            <iyz>0</iyz>
            <izz>0.01</izz>
          </inertia>
          <mass>1</mass>
          <pose frame=''>0 0 0 0 -0 0</pose>
        </inertial>
        <collision name='l_shoulder_geom'>
          <geometry>
            <sphere>
              <radius>0.055</radius>
            </sphere>
          </geometry>
          <surface>
            <friction>
              <ode>
                <mu>-1</mu>
                <mu2>-1</mu2>
                <fdir1>0 0 0</fdir1>
                <slip1>0</slip1>
                <slip2>0</slip2>
              </ode>
              <torsional>
                <ode/>
              </torsional>
            </friction>
            <bounce>
              <restitution_coefficient>0</restitution_coefficient>
              <threshold>100000</threshold>
            </bounce>
            <contact>
              <ode>
                <soft_cfm>0</soft_cfm>
                <soft_erp>0.2</soft_erp>
                <kp>1e+12</kp>
                <kd>1</kd>
                <max_vel>0</max_vel>
                <min_depth>0.001</min_depth>
              </ode>
            </contact>
          </surface>
          <laser_retro>0</laser_retro>
          <max_contacts>10</max_contacts>
        </collision>
        <visual name='l_shoulder_geom_visual'>
          <geometry>
            <sphere>
              <radius>0.055</radius>
            </sphere>
          </geometry>
          <cast_shadows>1</cast_shadows>
          <laser_retro>0</laser_retro>
          <transparency>0</transparency>
        </visual>
        <gravity>0</gravity>
        <self_collide>0</self_collide>
        <kinematic>0</kinematic>
        <enable_wind>0</enable_wind>
      </link>
      <link name='l_upper_arm'>
        <pose frame=''>0 0.3275 0.9225 0 -0 0</pose>
        <inertial>
          <inertia>
            <ixx>0.02</ixx>
            <ixy>0</ixy>
            <ixz>0</ixz>
            <iyy>0.02</iyy>
            <iyz>0</iyz>
            <izz>0.02</izz>
          </inertia>
          <mass>2</mass>
          <pose frame=''>0 0 0 0 -0 0</pose>
        </inertial>
        <collision name='l_upper_arm_geom'>
          <pose frame=''>0 0 -0.3 0 -0 0</pose>
          <geometry>
            <cylinder>
              <radius>0.055</radius>
              <length>0.6</length>
            </cylinder>
          </geometry>
          <surface>
            <friction>
              <ode>
                <mu>-1</mu>
                <mu2>-1</mu2>
                <fdir1>0 0 0</fdir1>
                <slip1>0</slip1>
                <slip2>0</slip2>
              </ode>
              <torsional>
                <ode/>
              </torsional>
            </friction>
            <bounce>
              <restitution_coefficient>0</restitution_coefficient>
              <threshold>100000</threshold>
            </bounce>
            <contact>
              <ode>
                <soft_cfm>0</soft_cfm>
                <soft_erp>0.2</soft_erp>
                <kp>1e+12</kp>
                <kd>1</kd>
                <max_vel>0</max_vel>
                <min_depth>0.001</min_depth>
              </ode>
            </contact>
          </surface>
          <laser_retro>0</laser_retro>
          <max_contacts>10</max_contacts>
        </collision>
        <visual name='l_upper_arm_geom_visual'>
          <pose frame=''>0 0 -0.3 0 -0 0</pose>
          <geometry>
            <cylinder>
              <radius>0.055</radius>
              <length>0.6</length>
            </cylinder>
          </geometry>
          <cast_shadows>1</cast_shadows>
          <laser_retro>0</laser_retro>
          <transparency>0</transparency>
        </visual>
        <gravity>0</gravity>
        <self_collide>0</self_collide>
        <kinematic>0</kinematic>
        <enable_wind>0</enable_wind>
      </link>
      <link name='l_forearm'>
        <pose frame=''>0 0.3275 0.3225 0 -0 0</pose>
        <inertial>
          <inertia>
            <ixx>0.01</ixx>
            <ixy>0</ixy>
            <ixz>0</ixz>
            <iyy>0.01</iyy>
            <iyz>0</iyz>
            <izz>0.01</izz>
          </inertia>
          <mass>1</mass>
          <pose frame=''>0 0 0 0 -0 0</pose>
        </inertial>
        <collision name='l_forearm_geom'>
          <pose frame=''>0 0 -0.225 0 -0 0</pose>
          <geometry>
            <cylinder>
              <radius>0.05</radius>
              <length>0.45</length>
            </cylinder>
          </geometry>
          <surface>
            <friction>
              <ode>
                <mu>-1</mu>
                <mu2>-1</mu2>
                <fdir1>0 0 0</fdir1>
                <slip1>0</slip1>
                <slip2>0</slip2>
              </ode>
              <torsional>
                <ode/>
              </torsional>
            </friction>
            <bounce>
              <restitution_coefficient>0</restitution_coefficient>
              <threshold>100000</threshold>
            </bounce>
            <contact>
              <ode>
                <soft_cfm>0</soft_cfm>
                <soft_erp>0.2</soft_erp>
                <kp>1e+12</kp>
                <kd>1</kd>
                <max_vel>0</max_vel>
                <min_depth>0.001</min_depth>
              </ode>
            </contact>
          </surface>
          <laser_retro>0</laser_retro>
          <max_contacts>10</max_contacts>
        </collision>
        <visual name='l_forearm_geom_visual'>
          <pose frame=''>0 0 -0.225 0 -0 0</pose>
          <geometry>
            <cylinder>
              <radius>0.05</radius>
              <length>0.45</length>
            </cylinder>
          </geometry>
          <cast_shadows>1</cast_shadows>
          <laser_retro>0</laser_retro>
          <transparency>0</transparency>
        </visual>
        <gravity>0</gravity>
        <self_collide>0</self_collide>
        <kinematic>0</kinematic>
        <enable_wind>0</enable_wind>
      </link>
      <link name='l_wrist'>
        <pose frame=''>0 0.3275 -0.1425 0 -0 0</pose>
        <inertial>
          <inertia>
            <ixx>0.01</ixx>
            <ixy>0</ixy>
            <ixz>0</ixz>
            <iyy>0.01</iyy>
            <iyz>0</iyz>
            <izz>0.01</izz>
          </inertia>
          <mass>1</mass>
          <pose frame=''>0 0 0 0 -0 0</pose>
        </inertial>
        <collision name='l_wrist_geom'>
          <geometry>
            <sphere>
              <radius>0.03</radius>
            </sphere>
          </geometry>
          <surface>
            <friction>
              <ode>
                <mu>-1</mu>
                <mu2>-1</mu2>
                <fdir1>0 0 0</fdir1>
                <slip1>0</slip1>
                <slip2>0</slip2>
              </ode>
              <torsional>
                <ode/>
              </torsional>
            </friction>
            <bounce>
              <restitution_coefficient>0</restitution_coefficient>
              <threshold>100000</threshold>
            </bounce>
            <contact>
              <ode>
                <soft_cfm>0</soft_cfm>
                <soft_erp>0.2</soft_erp>
                <kp>1e+12</kp>
                <kd>1</kd>
                <max_vel>0</max_vel>
                <min_depth>0.001</min_depth>
              </ode>
            </contact>
          </surface>
          <laser_retro>0</laser_retro>
          <max_contacts>10</max_contacts>
        </collision>
        <visual name='l_wrist_geom_visual'>
          <geometry>
            <sphere>
              <radius>0.03</radius>
            </sphere>
          </geometry>
          <cast_shadows>1</cast_shadows>
          <laser_retro>0</laser_retro>
          <transparency>0</transparency>
        </visual>
        <gravity>0</gravity>
        <self_collide>0</self_collide>
        <kinematic>0</kinematic>
        <enable_wind>0</enable_wind>
      </link>
      <link name='l_hand'>
        <pose frame=''>0 0.3275 -0.1575 0 -0 0</pose>
        <inertial>
          <inertia>
            <ixx>0.01</ixx>
            <ixy>0</ixy>
            <ixz>0</ixz>
            <iyy>0.01</iyy>
            <iyz>0</iyz>
            <izz>0.01</izz>
          </inertia>
          <mass>1</mass>
          <pose frame=''>0 0 0 0 -0 0</pose>
        </inertial>
        <collision name='l_hand_geom'>
          <pose frame=''>0 0 -0.1 0 -0 0</pose>
          <geometry>
            <box>
              <size>0.03 0.1 0.2</size>
            </box>
          </geometry>
          <surface>
            <friction>
              <ode>
                <mu>-1</mu>
                <mu2>-1</mu2>
                <fdir1>0 0 0</fdir1>
                <slip1>0</slip1>
                <slip2>0</slip2>
              </ode>
              <torsional>
                <ode/>
              </torsional>
            </friction>
            <bounce>
              <restitution_coefficient>0</restitution_coefficient>
              <threshold>100000</threshold>
            </bounce>
            <contact>
              <ode>
                <soft_cfm>0</soft_cfm>
                <soft_erp>0.2</soft_erp>
                <kp>1e+12</kp>
                <kd>1</kd>
                <max_vel>0</max_vel>
                <min_depth>0.001</min_depth>
              </ode>
            </contact>
          </surface>
          <laser_retro>0</laser_retro>
          <max_contacts>10</max_contacts>
        </collision>
        <visual name='l_hand_geom_visual'>
          <pose frame=''>0 0 -0.1 0 -0 0</pose>
          <geometry>
            <box>
              <size>0.03 0.1 0.2</size>
            </box>
          </geometry>
          <cast_shadows>1</cast_shadows>
          <laser_retro>0</laser_retro>
          <transparency>0</transparency>
        </visual>
        <gravity>0</gravity>
        <self_collide>0</self_collide>
        <kinematic>0</kinematic>
        <enable_wind>0</enable_wind>
      </link>
      <link name='neck'>
        <pose frame=''>0 0 0.95 0 -0 0</pose>
        <inertial>
          <inertia>
            <ixx>0.01</ixx>
            <ixy>0</ixy>
            <ixz>0</ixz>
            <iyy>0.01</iyy>
            <iyz>0</iyz>
            <izz>0.01</izz>
          </inertia>
          <mass>1</mass>
          <pose frame=''>0 0 0 0 -0 0</pose>
        </inertial>
        <collision name='neck_geom'>
          <pose frame=''>0 0 0.1 0 -0 0</pose>
          <geometry>
            <cylinder>
              <radius>0.075</radius>
              <length>0.2</length>
            </cylinder>
          </geometry>
          <surface>
            <friction>
              <ode>
                <mu>-1</mu>
                <mu2>-1</mu2>
                <fdir1>0 0 0</fdir1>
                <slip1>0</slip1>
                <slip2>0</slip2>
              </ode>
              <torsional>
                <ode/>
              </torsional>
            </friction>
            <bounce>
              <restitution_coefficient>0</restitution_coefficient>
              <threshold>100000</threshold>
            </bounce>
            <contact>
              <ode>
                <soft_cfm>0</soft_cfm>
                <soft_erp>0.2</soft_erp>
                <kp>1e+12</kp>
                <kd>1</kd>
                <max_vel>0</max_vel>
                <min_depth>0.001</min_depth>
              </ode>
            </contact>
          </surface>
          <laser_retro>0</laser_retro>
          <max_contacts>10</max_contacts>
        </collision>
        <visual name='neck_geom_visual'>
          <pose frame=''>0 0 0.1 0 -0 0</pose>
          <geometry>
            <cylinder>
              <radius>0.075</radius>
              <length>0.2</length>
            </cylinder>
          </geometry>
          <cast_shadows>1</cast_shadows>
          <laser_retro>0</laser_retro>
          <transparency>0</transparency>
        </visual>
        <gravity>0</gravity>
        <self_collide>0</self_collide>
        <kinematic>0</kinematic>
        <enable_wind>0</enable_wind>
      </link>
      <link name='head'>
        <pose frame=''>0 0 1.225 0 -0 0</pose>
        <inertial>
          <inertia>
            <ixx>0.1</ixx>
            <ixy>0</ixy>
            <ixz>0</ixz>
            <iyy>0.1</iyy>
            <iyz>0</iyz>
            <izz>0.1</izz>
          </inertia>
          <mass>10</mass>
          <pose frame=''>0 0 0 0 -0 0</pose>
        </inertial>
        <collision name='head_geom'>
          <geometry>
            <sphere>
              <radius>0.15</radius>
            </sphere>
          </geometry>
          <surface>
            <friction>
              <ode>
                <mu>-1</mu>
                <mu2>-1</mu2>
                <fdir1>0 0 0</fdir1>
                <slip1>0</slip1>
                <slip2>0</slip2>
              </ode>
              <torsional>
                <ode/>
              </torsional>
            </friction>
            <bounce>
              <restitution_coefficient>0</restitution_coefficient>
              <threshold>100000</threshold>
            </bounce>
            <contact>
              <ode>
                <soft_cfm>0</soft_cfm>
                <soft_erp>0.2</soft_erp>
                <kp>1e+12</kp>
                <kd>1</kd>
                <max_vel>0</max_vel>
                <min_depth>0.001</min_depth>
              </ode>
            </contact>
          </surface>
          <laser_retro>0</laser_retro>
          <max_contacts>10</max_contacts>
        </collision>
        <visual name='head_geom_visual'>
          <geometry>
            <sphere>
              <radius>0.15</radius>
            </sphere>
          </geometry>
          <cast_shadows>1</cast_shadows>
          <laser_retro>0</laser_retro>
          <transparency>0</transparency>
        </visual>
        <gravity>0</gravity>
        <self_collide>0</self_collide>
        <kinematic>0</kinematic>
        <enable_wind>0</enable_wind>
      </link>
      <link name='r_shoulder'>
        <pose frame=''>0 -0.3275 0.9225 0 -0 0</pose>
        <inertial>
          <inertia>
            <ixx>0.01</ixx>
            <ixy>0</ixy>
            <ixz>0</ixz>
            <iyy>0.01</iyy>
            <iyz>0</iyz>
            <izz>0.01</izz>
          </inertia>
          <mass>1</mass>
          <pose frame=''>0 0 0 0 -0 0</pose>
        </inertial>
        <collision name='r_shoulder_geom'>
          <geometry>
            <sphere>
              <radius>0.055</radius>
            </sphere>
          </geometry>
          <surface>
            <friction>
              <ode>
                <mu>-1</mu>
                <mu2>-1</mu2>
                <fdir1>0 0 0</fdir1>
                <slip1>0</slip1>
                <slip2>0</slip2>
              </ode>
              <torsional>
                <ode/>
              </torsional>
            </friction>
            <bounce>
              <restitution_coefficient>0</restitution_coefficient>
              <threshold>100000</threshold>
            </bounce>
            <contact>
              <ode>
                <soft_cfm>0</soft_cfm>
                <soft_erp>0.2</soft_erp>
                <kp>1e+12</kp>
                <kd>1</kd>
                <max_vel>0</max_vel>
                <min_depth>0.001</min_depth>
              </ode>
            </contact>
          </surface>
          <laser_retro>0</laser_retro>
          <max_contacts>10</max_contacts>
        </collision>
        <visual name='r_shoulder_geom_visual'>
          <geometry>
            <sphere>
              <radius>0.055</radius>
            </sphere>
          </geometry>
          <cast_shadows>1</cast_shadows>
          <laser_retro>0</laser_retro>
          <transparency>0</transparency>
        </visual>
        <gravity>0</gravity>
        <self_collide>0</self_collide>
        <kinematic>0</kinematic>
        <enable_wind>0</enable_wind>
      </link>
      <link name='r_upper_arm'>
        <pose frame=''>0 -0.3275 0.9225 0 -0 0</pose>
        <inertial>
          <inertia>
            <ixx>0.02</ixx>
            <ixy>0</ixy>
            <ixz>0</ixz>
            <iyy>0.02</iyy>
            <iyz>0</iyz>
            <izz>0.02</izz>
          </inertia>
          <mass>2</mass>
          <pose frame=''>0 0 0 0 -0 0</pose>
        </inertial>
        <collision name='r_upper_arm_geom'>
          <pose frame=''>0 0 -0.3 0 -0 0</pose>
          <geometry>
            <cylinder>
              <radius>0.055</radius>
              <length>0.6</length>
            </cylinder>
          </geometry>
          <surface>
            <friction>
              <ode>
                <mu>-1</mu>
                <mu2>-1</mu2>
                <fdir1>0 0 0</fdir1>
                <slip1>0</slip1>
                <slip2>0</slip2>
              </ode>
              <torsional>
                <ode/>
              </torsional>
            </friction>
            <bounce>
              <restitution_coefficient>0</restitution_coefficient>
              <threshold>100000</threshold>
            </bounce>
            <contact>
              <ode>
                <soft_cfm>0</soft_cfm>
                <soft_erp>0.2</soft_erp>
                <kp>1e+12</kp>
                <kd>1</kd>
                <max_vel>0</max_vel>
                <min_depth>0.001</min_depth>
              </ode>
            </contact>
          </surface>
          <laser_retro>0</laser_retro>
          <max_contacts>10</max_contacts>
        </collision>
        <visual name='r_upper_arm_geom_visual'>
          <pose frame=''>0 0 -0.3 0 -0 0</pose>
          <geometry>
            <cylinder>
              <radius>0.055</radius>
              <length>0.6</length>
            </cylinder>
          </geometry>
          <cast_shadows>1</cast_shadows>
          <laser_retro>0</laser_retro>
          <transparency>0</transparency>
        </visual>
        <gravity>0</gravity>
        <self_collide>0</self_collide>
        <kinematic>0</kinematic>
        <enable_wind>0</enable_wind>
      </link>
      <link name='r_forearm'>
        <pose frame=''>0 -0.3275 0.3225 0 -0 0</pose>
        <inertial>
          <inertia>
            <ixx>0.01</ixx>
            <ixy>0</ixy>
            <ixz>0</ixz>
            <iyy>0.01</iyy>
            <iyz>0</iyz>
            <izz>0.01</izz>
          </inertia>
          <mass>1</mass>
          <pose frame=''>0 0 0 0 -0 0</pose>
        </inertial>
        <collision name='r_forearm_geom'>
          <pose frame=''>0 0 -0.225 0 -0 0</pose>
          <geometry>
            <cylinder>
              <radius>0.05</radius>
              <length>0.45</length>
            </cylinder>
          </geometry>
          <surface>
            <friction>
              <ode>
                <mu>-1</mu>
                <mu2>-1</mu2>
                <fdir1>0 0 0</fdir1>
                <slip1>0</slip1>
                <slip2>0</slip2>
              </ode>
              <torsional>
                <ode/>
              </torsional>
            </friction>
            <bounce>
              <restitution_coefficient>0</restitution_coefficient>
              <threshold>100000</threshold>
            </bounce>
            <contact>
              <ode>
                <soft_cfm>0</soft_cfm>
                <soft_erp>0.2</soft_erp>
                <kp>1e+12</kp>
                <kd>1</kd>
                <max_vel>0</max_vel>
                <min_depth>0.001</min_depth>
              </ode>
            </contact>
          </surface>
          <laser_retro>0</laser_retro>
          <max_contacts>10</max_contacts>
        </collision>
        <visual name='r_forearm_geom_visual'>
          <pose frame=''>0 0 -0.225 0 -0 0</pose>
          <geometry>
            <cylinder>
              <radius>0.05</radius>
              <length>0.45</length>
            </cylinder>
          </geometry>
          <cast_shadows>1</cast_shadows>
          <laser_retro>0</laser_retro>
          <transparency>0</transparency>
        </visual>
        <gravity>0</gravity>
        <self_collide>0</self_collide>
        <kinematic>0</kinematic>
        <enable_wind>0</enable_wind>
      </link>
      <link name='r_wrist'>
        <pose frame=''>0 -0.3275 -0.1425 0 -0 0</pose>
        <inertial>
          <inertia>
            <ixx>0.01</ixx>
            <ixy>0</ixy>
            <ixz>0</ixz>
            <iyy>0.01</iyy>
            <iyz>0</iyz>
            <izz>0.01</izz>
          </inertia>
          <mass>1</mass>
          <pose frame=''>0 0 0 0 -0 0</pose>
        </inertial>
        <collision name='r_wrist_geom'>
          <geometry>
            <sphere>
              <radius>0.03</radius>
            </sphere>
          </geometry>
          <surface>
            <friction>
              <ode>
                <mu>-1</mu>
                <mu2>-1</mu2>
                <fdir1>0 0 0</fdir1>
                <slip1>0</slip1>
                <slip2>0</slip2>
              </ode>
              <torsional>
                <ode/>
              </torsional>
            </friction>
            <bounce>
              <restitution_coefficient>0</restitution_coefficient>
              <threshold>100000</threshold>
            </bounce>
            <contact>
              <ode>
                <soft_cfm>0</soft_cfm>
                <soft_erp>0.2</soft_erp>
                <kp>1e+12</kp>
                <kd>1</kd>
                <max_vel>0</max_vel>
                <min_depth>0.001</min_depth>
              </ode>
            </contact>
          </surface>
          <laser_retro>0</laser_retro>
          <max_contacts>10</max_contacts>
        </collision>
        <visual name='r_wrist_geom_visual'>
          <geometry>
            <sphere>
              <radius>0.03</radius>
            </sphere>
          </geometry>
          <cast_shadows>1</cast_shadows>
          <laser_retro>0</laser_retro>
          <transparency>0</transparency>
        </visual>
        <gravity>0</gravity>
        <self_collide>0</self_collide>
        <kinematic>0</kinematic>
        <enable_wind>0</enable_wind>
      </link>
      <link name='r_hand'>
        <pose frame=''>0 -0.3275 -0.1575 0 -0 0</pose>
        <inertial>
          <inertia>
            <ixx>0.01</ixx>
            <ixy>0</ixy>
            <ixz>0</ixz>
            <iyy>0.01</iyy>
            <iyz>0</iyz>
            <izz>0.01</izz>
          </inertia>
          <mass>1</mass>
          <pose frame=''>0 0 0 0 -0 0</pose>
        </inertial>
        <collision name='r_hand_geom'>
          <pose frame=''>0 0 -0.1 0 -0 0</pose>
          <geometry>
            <box>
              <size>0.03 0.1 0.2</size>
            </box>
          </geometry>
          <surface>
            <friction>
              <ode>
                <mu>-1</mu>
                <mu2>-1</mu2>
                <fdir1>0 0 0</fdir1>
                <slip1>0</slip1>
                <slip2>0</slip2>
              </ode>
              <torsional>
                <ode/>
              </torsional>
            </friction>
            <bounce>
              <restitution_coefficient>0</restitution_coefficient>
              <threshold>100000</threshold>
            </bounce>
            <contact>
              <ode>
                <soft_cfm>0</soft_cfm>
                <soft_erp>0.2</soft_erp>
                <kp>1e+12</kp>
                <kd>1</kd>
                <max_vel>0</max_vel>
                <min_depth>0.001</min_depth>
              </ode>
            </contact>
          </surface>
          <laser_retro>0</laser_retro>
          <max_contacts>10</max_contacts>
        </collision>
        <visual name='r_hand_geom_visual'>
          <pose frame=''>0 0 -0.1 0 -0 0</pose>
          <geometry>
            <box>
              <size>0.03 0.1 0.2</size>
            </box>
          </geometry>
          <cast_shadows>1</cast_shadows>
          <laser_retro>0</laser_retro>
          <transparency>0</transparency>
        </visual>
        <gravity>0</gravity>
        <self_collide>0</self_collide>
        <kinematic>0</kinematic>
        <enable_wind>0</enable_wind>
      </link>
      <joint name='l_thigh_pan_joint' type='revolute'>
        <parent>hip</parent>
        <child>l_thigh_pan</child>
        <axis>
          <dynamics>
            <damping>0</damping>
            <friction>0</friction>
            <spring_reference>0</spring_reference>
            <spring_stiffness>0</spring_stiffness>
          </dynamics>
          <limit>
            <lower>-1.5708</lower>
            <upper>1.5708</upper>
            <effort>0</effort>
            <velocity>0</velocity>
          </limit>
          <xyz>0 0 1</xyz>
          <use_parent_model_frame>0</use_parent_model_frame>
        </axis>
      </joint>
      <joint name='l_thigh_lift_joint' type='revolute'>
        <parent>l_thigh_pan</parent>
        <child>l_thigh_lift</child>
        <axis>
          <dynamics>
            <damping>0</damping>
            <friction>0</friction>
            <spring_reference>0</spring_reference>
            <spring_stiffness>0</spring_stiffness>
          </dynamics>
          <limit>
            <lower>-1.5708</lower>
            <upper>1.5708</upper>
            <effort>0</effort>
            <velocity>0</velocity>
          </limit>
          <xyz>0 1 0</xyz>
          <use_parent_model_frame>0</use_parent_model_frame>
        </axis>
      </joint>
      <joint name='l_calf_joint' type='revolute'>
        <parent>l_thigh_lift</parent>
        <child>l_calf</child>
        <axis>
          <dynamics>
            <damping>0</damping>
            <friction>0</friction>
            <spring_reference>0</spring_reference>
            <spring_stiffness>0</spring_stiffness>
          </dynamics>
          <limit>
            <lower>-1.5708</lower>
            <upper>1.5708</upper>
            <effort>0</effort>
            <velocity>0</velocity>
          </limit>
          <xyz>0 1 0</xyz>
          <use_parent_model_frame>0</use_parent_model_frame>
        </axis>
      </joint>
      <joint name='l_ankle_joint' type='revolute'>
        <parent>l_calf</parent>
        <child>l_ankle</child>
        <axis>
          <dynamics>
            <damping>0</damping>
            <friction>0</friction>
            <spring_reference>0</spring_reference>
            <spring_stiffness>0</spring_stiffness>
          </dynamics>
          <limit>
            <lower>-1.5708</lower>
            <upper>1.5708</upper>
            <effort>0</effort>
            <velocity>0</velocity>
          </limit>
          <xyz>0 1 0</xyz>
          <use_parent_model_frame>0</use_parent_model_frame>
        </axis>
      </joint>
      <joint name='l_foot_joint' type='revolute'>
        <parent>l_ankle</parent>
        <child>l_foot</child>
        <axis>
          <dynamics>
            <damping>0</damping>
            <friction>0</friction>
            <spring_reference>0</spring_reference>
            <spring_stiffness>0</spring_stiffness>
          </dynamics>
          <limit>
            <lower>-1.5708</lower>
            <upper>1.5708</upper>
            <effort>0</effort>
            <velocity>0</velocity>
          </limit>
          <xyz>1 0 0</xyz>
          <use_parent_model_frame>0</use_parent_model_frame>
        </axis>
      </joint>
      <joint name='r_thigh_pan_joint' type='revolute'>
        <parent>hip</parent>
        <child>r_thigh_pan</child>
        <axis>
          <dynamics>
            <damping>0</damping>
            <friction>0</friction>
            <spring_reference>0</spring_reference>
            <spring_stiffness>0</spring_stiffness>
          </dynamics>
          <limit>
            <lower>-1.5708</lower>
            <upper>1.5708</upper>
            <effort>0</effort>
            <velocity>0</velocity>
          </limit>
          <xyz>0 0 1</xyz>
          <use_parent_model_frame>0</use_parent_model_frame>
        </axis>
      </joint>
      <joint name='r_thigh_lift_joint' type='revolute'>
        <parent>r_thigh_pan</parent>
        <child>r_thigh_lift</child>
        <axis>
          <dynamics>
            <damping>0</damping>
            <friction>0</friction>
            <spring_reference>0</spring_reference>
            <spring_stiffness>0</spring_stiffness>
          </dynamics>
          <limit>
            <lower>-1.5708</lower>
            <upper>1.5708</upper>
            <effort>0</effort>
            <velocity>0</velocity>
          </limit>
          <xyz>0 1 0</xyz>
          <use_parent_model_frame>0</use_parent_model_frame>
        </axis>
      </joint>
      <joint name='r_calf_joint' type='revolute'>
        <parent>r_thigh_lift</parent>
        <child>r_calf</child>
        <axis>
          <dynamics>
            <damping>0</damping>
            <friction>0</friction>
            <spring_reference>0</spring_reference>
            <spring_stiffness>0</spring_stiffness>
          </dynamics>
          <limit>
            <lower>-1.5708</lower>
            <upper>1.5708</upper>
            <effort>0</effort>
            <velocity>0</velocity>
          </limit>
          <xyz>0 1 0</xyz>
          <use_parent_model_frame>0</use_parent_model_frame>
        </axis>
      </joint>
      <joint name='r_ankle_joint' type='revolute'>
        <parent>r_calf</parent>
        <child>r_ankle</child>
        <axis>
          <dynamics>
            <damping>0</damping>
            <friction>0</friction>
            <spring_reference>0</spring_reference>
            <spring_stiffness>0</spring_stiffness>
          </dynamics>
          <limit>
            <lower>-1.5708</lower>
            <upper>1.5708</upper>
            <effort>0</effort>
            <velocity>0</velocity>
          </limit>
          <xyz>0 1 0</xyz>
          <use_parent_model_frame>0</use_parent_model_frame>
        </axis>
      </joint>
      <joint name='r_foot_joint' type='revolute'>
        <parent>r_ankle</parent>
        <child>r_foot</child>
        <axis>
          <dynamics>
            <damping>0</damping>
            <friction>0</friction>
            <spring_reference>0</spring_reference>
            <spring_stiffness>0</spring_stiffness>
          </dynamics>
          <limit>
            <lower>-1.5708</lower>
            <upper>1.5708</upper>
            <effort>0</effort>
            <velocity>0</velocity>
          </limit>
          <xyz>1 0 0</xyz>
          <use_parent_model_frame>0</use_parent_model_frame>
        </axis>
      </joint>
      <joint name='torso_joint' type='revolute'>
        <parent>hip</parent>
        <child>torso</child>
        <axis>
          <dynamics>
            <damping>0</damping>
            <friction>0</friction>
            <spring_reference>0</spring_reference>
            <spring_stiffness>0</spring_stiffness>
          </dynamics>
          <limit>
            <lower>-1.5708</lower>
            <upper>1.5708</upper>
            <effort>0</effort>
            <velocity>0</velocity>
          </limit>
          <xyz>0 1 0</xyz>
          <use_parent_model_frame>0</use_parent_model_frame>
        </axis>
      </joint>
      <joint name='l_shoulder_joint' type='revolute'>
        <parent>torso</parent>
        <child>l_shoulder</child>
        <axis>
          <dynamics>
            <damping>0</damping>
            <friction>0</friction>
            <spring_reference>0</spring_reference>
            <spring_stiffness>0</spring_stiffness>
          </dynamics>
          <limit>
            <lower>-1.5708</lower>
            <upper>1.5708</upper>
            <effort>0</effort>
            <velocity>0</velocity>
          </limit>
          <xyz>1 0 0</xyz>
          <use_parent_model_frame>0</use_parent_model_frame>
        </axis>
      </joint>
      <joint name='l_upper_arm_joint' type='revolute'>
        <parent>l_shoulder</parent>
        <child>l_upper_arm</child>
        <axis>
          <dynamics>
            <damping>0</damping>
            <friction>0</friction>
            <spring_reference>0</spring_reference>
            <spring_stiffness>0</spring_stiffness>
          </dynamics>
          <limit>
            <lower>-1.5708</lower>
            <upper>1.5708</upper>
            <effort>0</effort>
            <velocity>0</velocity>
          </limit>
          <xyz>0 1 0</xyz>
          <use_parent_model_frame>0</use_parent_model_frame>
        </axis>
      </joint>
      <joint name='l_forearm_joint' type='revolute'>
        <parent>l_upper_arm</parent>
        <child>l_forearm</child>
        <axis>
          <dynamics>
            <damping>0</damping>
            <friction>0</friction>
            <spring_reference>0</spring_reference>
            <spring_stiffness>0</spring_stiffness>
          </dynamics>
          <limit>
            <lower>-1.5708</lower>
            <upper>1.5708</upper>
            <effort>0</effort>
            <velocity>0</velocity>
          </limit>
          <xyz>0 1 0</xyz>
          <use_parent_model_frame>0</use_parent_model_frame>
        </axis>
      </joint>
      <joint name='l_wrist_joint' type='revolute'>
        <parent>l_forearm</parent>
        <child>l_wrist</child>
        <axis>
          <dynamics>
            <damping>0</damping>
            <friction>0</friction>
            <spring_reference>0</spring_reference>
            <spring_stiffness>0</spring_stiffness>
          </dynamics>
          <limit>
            <lower>-1.5708</lower>
            <upper>1.5708</upper>
            <effort>0</effort>
            <velocity>0</velocity>
          </limit>
          <xyz>0 1 0</xyz>
          <use_parent_model_frame>0</use_parent_model_frame>
        </axis>
      </joint>
      <joint name='l_hand_joint' type='revolute'>
        <parent>l_wrist</parent>
        <child>l_hand</child>
        <axis>
          <dynamics>
            <damping>0</damping>
            <friction>0</friction>
            <spring_reference>0</spring_reference>
            <spring_stiffness>0</spring_stiffness>
          </dynamics>
          <limit>
            <lower>-1.5708</lower>
            <upper>1.5708</upper>
            <effort>0</effort>
            <velocity>0</velocity>
          </limit>
          <xyz>0 1 0</xyz>
          <use_parent_model_frame>0</use_parent_model_frame>
        </axis>
      </joint>
      <joint name='neck_joint' type='revolute'>
        <parent>torso</parent>
        <child>neck</child>
        <axis>
          <dynamics>
            <damping>0</damping>
            <friction>0</friction>
            <spring_reference>0</spring_reference>
            <spring_stiffness>0</spring_stiffness>
          </dynamics>
          <limit>
            <lower>-1.5708</lower>
            <upper>1.5708</upper>
            <effort>0</effort>
            <velocity>0</velocity>
          </limit>
          <xyz>0 0 1</xyz>
          <use_parent_model_frame>0</use_parent_model_frame>
        </axis>
      </joint>
      <joint name='head_joint' type='revolute'>
        <parent>neck</parent>
        <child>head</child>
        <axis>
          <dynamics>
            <damping>0</damping>
            <friction>0</friction>
            <spring_reference>0</spring_reference>
            <spring_stiffness>0</spring_stiffness>
          </dynamics>
          <limit>
            <lower>-1.5708</lower>
            <upper>1.5708</upper>
            <effort>0</effort>
            <velocity>0</velocity>
          </limit>
          <xyz>0 1 0</xyz>
          <use_parent_model_frame>0</use_parent_model_frame>
        </axis>
      </joint>
      <joint name='r_shoulder_joint' type='revolute'>
        <parent>torso</parent>
        <child>r_shoulder</child>
        <axis>
          <dynamics>
            <damping>0</damping>
            <friction>0</friction>
            <spring_reference>0</spring_reference>
            <spring_stiffness>0</spring_stiffness>
          </dynamics>
          <limit>
            <lower>-1.5708</lower>
            <upper>1.5708</upper>
            <effort>0</effort>
            <velocity>0</velocity>
          </limit>
          <xyz>1 0 0</xyz>
          <use_parent_model_frame>0</use_parent_model_frame>
        </axis>
      </joint>
      <joint name='r_upper_arm_joint' type='revolute'>
        <parent>r_shoulder</parent>
        <child>r_upper_arm</child>
        <axis>
          <dynamics>
            <damping>0</damping>
            <friction>0</friction>
            <spring_reference>0</spring_reference>
            <spring_stiffness>0</spring_stiffness>
          </dynamics>
          <limit>
            <lower>-1.5708</lower>
            <upper>1.5708</upper>
            <effort>0</effort>
            <velocity>0</velocity>
          </limit>
          <xyz>0 1 0</xyz>
          <use_parent_model_frame>0</use_parent_model_frame>
        </axis>
      </joint>
      <joint name='r_forearm_joint' type='revolute'>
        <parent>r_upper_arm</parent>
        <child>r_forearm</child>
        <axis>
          <dynamics>
            <damping>0</damping>
            <friction>0</friction>
            <spring_reference>0</spring_reference>
            <spring_stiffness>0</spring_stiffness>
          </dynamics>
          <limit>
            <lower>-1.5708</lower>
            <upper>1.5708</upper>
            <effort>0</effort>
            <velocity>0</velocity>
          </limit>
          <xyz>0 1 0</xyz>
          <use_parent_model_frame>0</use_parent_model_frame>
        </axis>
      </joint>
      <joint name='r_wrist_joint' type='revolute'>
        <parent>r_forearm</parent>
        <child>r_wrist</child>
        <axis>
          <dynamics>
            <damping>0</damping>
            <friction>0</friction>
            <spring_reference>0</spring_reference>
            <spring_stiffness>0</spring_stiffness>
          </dynamics>
          <limit>
            <lower>-1.5708</lower>
            <upper>1.5708</upper>
            <effort>0</effort>
            <velocity>0</velocity>
          </limit>
          <xyz>0 1 0</xyz>
          <use_parent_model_frame>0</use_parent_model_frame>
        </axis>
      </joint>
      <joint name='r_hand_joint' type='revolute'>
        <parent>r_wrist</parent>
        <child>r_hand</child>
        <axis>
          <dynamics>
            <damping>0</damping>
            <friction>0</friction>
            <spring_reference>0</spring_reference>
            <spring_stiffness>0</spring_stiffness>
          </dynamics>
          <limit>
            <lower>-1.5708</lower>
            <upper>1.5708</upper>
            <effort>0</effort>
            <velocity>0</velocity>
          </limit>
          <xyz>0 1 0</xyz>
          <use_parent_model_frame>0</use_parent_model_frame>
        </axis>
      </joint>
      <static>0</static>
    </model>
    <model name='model_0'>
      <model name='cart_front_steer'>
        <link name='chassis'>
          <pose frame=''>0 0 0.15 0 -0 0</pose>
          <inertial>
            <pose frame=''>0.1 0 0 0 -0 0</pose>
            <mass>10</mass>
            <inertia>
              <ixx>0.216667</ixx>
              <iyy>0.841667</iyy>
              <izz>1.04167</izz>
              <ixy>0</ixy>
              <ixz>0</ixz>
              <iyz>0</iyz>
            </inertia>
          </inertial>
          <collision name='collision'>
            <geometry>
              <box>
                <size>1 0.5 0.1</size>
              </box>
            </geometry>
            <max_contacts>10</max_contacts>
            <surface>
              <contact>
                <ode/>
              </contact>
              <bounce/>
              <friction>
                <torsional>
                  <ode/>
                </torsional>
                <ode/>
              </friction>
            </surface>
          </collision>
          <visual name='visual'>
            <geometry>
              <box>
                <size>1 0.5 0.1</size>
              </box>
            </geometry>
            <material>
              <script>
                <uri>file://media/materials/scripts/gazebo.material</uri>
                <name>Gazebo/Grey</name>
              </script>
            </material>
          </visual>
          <self_collide>0</self_collide>
          <enable_wind>0</enable_wind>
          <kinematic>0</kinematic>
        </link>
        <link name='wheel_front_left'>
          <pose frame=''>0.5 0.298 0.15 -1.5708 -0.087266 0</pose>
          <inertial>
            <mass>0.5</mass>
            <inertia>
              <ixx>0.00307917</ixx>
              <iyy>0.00307917</iyy>
              <izz>0.005625</izz>
              <ixy>0</ixy>
              <ixz>0</ixz>
              <iyz>0</iyz>
            </inertia>
            <pose frame=''>0 0 0 0 -0 0</pose>
          </inertial>
          <collision name='collision'>
            <geometry>
              <cylinder>
                <radius>0.15</radius>
                <length>0.08</length>
              </cylinder>
            </geometry>
            <max_contacts>10</max_contacts>
            <surface>
              <contact>
                <ode/>
              </contact>
              <bounce/>
              <friction>
                <torsional>
                  <ode/>
                </torsional>
                <ode/>
              </friction>
            </surface>
          </collision>
          <visual name='visual'>
            <geometry>
              <cylinder>
                <radius>0.15</radius>
                <length>0.08</length>
              </cylinder>
            </geometry>
            <material>
              <script>
                <uri>file://media/materials/scripts/gazebo.material</uri>
                <name>Gazebo/Black</name>
              </script>
            </material>
          </visual>
          <self_collide>0</self_collide>
          <enable_wind>0</enable_wind>
          <kinematic>0</kinematic>
        </link>
        <joint name='wheel_front_left_steer_spin' type='universal'>
          <parent>chassis</parent>
          <child>wheel_front_left</child>
          <axis>
            <xyz>0 -1 0</xyz>
            <limit>
              <lower>-0.610865</lower>
              <upper>0.610865</upper>
            </limit>
            <dynamics>
              <spring_reference>0</spring_reference>
              <spring_stiffness>0</spring_stiffness>
            </dynamics>
            <use_parent_model_frame>0</use_parent_model_frame>
          </axis>
          <axis2>
            <xyz>0 0 1</xyz>
            <limit>
              <upper>1e+16</upper>
              <lower>-1e+16</lower>
            </limit>
            <dynamics>
              <spring_reference>0</spring_reference>
              <spring_stiffness>0</spring_stiffness>
            </dynamics>
            <use_parent_model_frame>0</use_parent_model_frame>
          </axis2>
        </joint>
        <link name='wheel_front_right'>
          <pose frame=''>0.5 -0.298 0.15 -1.5708 -0.087266 0</pose>
          <inertial>
            <mass>0.5</mass>
            <inertia>
              <ixx>0.00307917</ixx>
              <iyy>0.00307917</iyy>
              <izz>0.005625</izz>
              <ixy>0</ixy>
              <ixz>0</ixz>
              <iyz>0</iyz>
            </inertia>
            <pose frame=''>0 0 0 0 -0 0</pose>
          </inertial>
          <collision name='collision'>
            <geometry>
              <cylinder>
                <radius>0.15</radius>
                <length>0.08</length>
              </cylinder>
            </geometry>
            <max_contacts>10</max_contacts>
            <surface>
              <contact>
                <ode/>
              </contact>
              <bounce/>
              <friction>
                <torsional>
                  <ode/>
                </torsional>
                <ode/>
              </friction>
            </surface>
          </collision>
          <visual name='visual'>
            <geometry>
              <cylinder>
                <radius>0.15</radius>
                <length>0.08</length>
              </cylinder>
            </geometry>
            <material>
              <script>
                <uri>file://media/materials/scripts/gazebo.material</uri>
                <name>Gazebo/Black</name>
              </script>
            </material>
          </visual>
          <self_collide>0</self_collide>
          <enable_wind>0</enable_wind>
          <kinematic>0</kinematic>
        </link>
        <joint name='wheel_front_right_steer_spin' type='universal'>
          <parent>chassis</parent>
          <child>wheel_front_right</child>
          <axis>
            <xyz>0 -1 0</xyz>
            <limit>
              <lower>-0.610865</lower>
              <upper>0.610865</upper>
            </limit>
            <dynamics>
              <spring_reference>0</spring_reference>
              <spring_stiffness>0</spring_stiffness>
            </dynamics>
            <use_parent_model_frame>0</use_parent_model_frame>
          </axis>
          <axis2>
            <xyz>0 0 1</xyz>
            <limit>
              <upper>1e+16</upper>
              <lower>-1e+16</lower>
            </limit>
            <dynamics>
              <spring_reference>0</spring_reference>
              <spring_stiffness>0</spring_stiffness>
            </dynamics>
            <use_parent_model_frame>0</use_parent_model_frame>
          </axis2>
        </joint>
        <link name='wheel_rear_left'>
          <pose frame=''>-0.5 0.298 0.15 -1.5708 0 0</pose>
          <inertial>
            <mass>0.5</mass>
            <inertia>
              <ixx>0.00307917</ixx>
              <iyy>0.00307917</iyy>
              <izz>0.005625</izz>
              <ixy>0</ixy>
              <ixz>0</ixz>
              <iyz>0</iyz>
            </inertia>
            <pose frame=''>0 0 0 0 -0 0</pose>
          </inertial>
          <collision name='collision'>
            <geometry>
              <cylinder>
                <radius>0.15</radius>
                <length>0.08</length>
              </cylinder>
            </geometry>
            <max_contacts>10</max_contacts>
            <surface>
              <contact>
                <ode/>
              </contact>
              <bounce/>
              <friction>
                <torsional>
                  <ode/>
                </torsional>
                <ode/>
              </friction>
            </surface>
          </collision>
          <visual name='visual'>
            <geometry>
              <cylinder>
                <radius>0.15</radius>
                <length>0.08</length>
              </cylinder>
            </geometry>
            <material>
              <script>
                <uri>file://media/materials/scripts/gazebo.material</uri>
                <name>Gazebo/Black</name>
              </script>
            </material>
          </visual>
          <self_collide>0</self_collide>
          <enable_wind>0</enable_wind>
          <kinematic>0</kinematic>
        </link>
        <joint name='wheel_rear_left_spin' type='revolute'>
          <parent>chassis</parent>
          <child>wheel_rear_left</child>
          <axis>
            <xyz>0 0 1</xyz>
            <limit>
              <lower>-1e+16</lower>
              <upper>1e+16</upper>
            </limit>
            <dynamics>
              <spring_reference>0</spring_reference>
              <spring_stiffness>0</spring_stiffness>
            </dynamics>
            <use_parent_model_frame>0</use_parent_model_frame>
          </axis>
        </joint>
        <link name='wheel_rear_right'>
          <pose frame=''>-0.5 -0.298 0.15 -1.5708 0 0</pose>
          <inertial>
            <mass>0.5</mass>
            <inertia>
              <ixx>0.00307917</ixx>
              <iyy>0.00307917</iyy>
              <izz>0.005625</izz>
              <ixy>0</ixy>
              <ixz>0</ixz>
              <iyz>0</iyz>
            </inertia>
            <pose frame=''>0 0 0 0 -0 0</pose>
          </inertial>
          <collision name='collision'>
            <geometry>
              <cylinder>
                <radius>0.15</radius>
                <length>0.08</length>
              </cylinder>
            </geometry>
            <max_contacts>10</max_contacts>
            <surface>
              <contact>
                <ode/>
              </contact>
              <bounce/>
              <friction>
                <torsional>
                  <ode/>
                </torsional>
                <ode/>
              </friction>
            </surface>
          </collision>
          <visual name='visual'>
            <geometry>
              <cylinder>
                <radius>0.15</radius>
                <length>0.08</length>
              </cylinder>
            </geometry>
            <material>
              <script>
                <uri>file://media/materials/scripts/gazebo.material</uri>
                <name>Gazebo/Black</name>
              </script>
            </material>
          </visual>
          <self_collide>0</self_collide>
          <enable_wind>0</enable_wind>
          <kinematic>0</kinematic>
        </link>
        <joint name='wheel_rear_right_spin' type='revolute'>
          <parent>chassis</parent>
          <child>wheel_rear_right</child>
          <axis>
            <xyz>0 0 1</xyz>
            <limit>
              <lower>-1e+16</lower>
              <upper>1e+16</upper>
            </limit>
            <dynamics>
              <spring_reference>0</spring_reference>
              <spring_stiffness>0</spring_stiffness>
            </dynamics>
            <use_parent_model_frame>0</use_parent_model_frame>
          </axis>
        </joint>
        <pose frame=''>-1.06061 0.576576 0 0 -0 0</pose>
      </model>
      <static>0</static>
      <allow_auto_disable>0</allow_auto_disable>
      <pose frame=''>3.53497 0.623943 0 0 -0 0</pose>
    </model>
    <model name='my_ball'>
      <link name='link_0'>
        <inertial>
          <mass>1</mass>
          <inertia>
            <ixx>0.1</ixx>
            <ixy>0</ixy>
            <ixz>0</ixz>
            <iyy>0.1</iyy>
            <iyz>0</iyz>
            <izz>0.1</izz>
          </inertia>
          <pose frame=''>0 0 0 0 -0 0</pose>
        </inertial>
        <pose frame=''>0 -0 0 0 -0 0</pose>
        <gravity>1</gravity>
        <self_collide>0</self_collide>
        <kinematic>0</kinematic>
        <enable_wind>0</enable_wind>
        <visual name='visual'>
          <pose frame=''>0 0 0 0 -0 0</pose>
          <geometry>
            <sphere>
              <radius>0.1</radius>
            </sphere>
          </geometry>
          <material>
            <lighting>1</lighting>
            <script>
              <uri>file://media/materials/scripts/gazebo.material</uri>
              <name>Gazebo/Grey</name>
            </script>
            <shader type='vertex'>
              <normal_map>__default__</normal_map>
            </shader>
            <ambient>1 1 1 1</ambient>
            <diffuse>1 1 1 1</diffuse>
            <specular>1 1 1 1</specular>
            <emissive>1 1 1 1</emissive>
          </material>
          <transparency>0</transparency>
          <cast_shadows>1</cast_shadows>
        </visual>
        <collision name='collision'>
          <laser_retro>0</laser_retro>
          <max_contacts>10</max_contacts>
          <pose frame=''>0 0 0 0 -0 0</pose>
          <geometry>
            <sphere>
              <radius>0.1</radius>
            </sphere>
          </geometry>
          <surface>
            <friction>
              <ode>
                <mu>1</mu>
                <mu2>1</mu2>
                <fdir1>0 0 0</fdir1>
                <slip1>0</slip1>
                <slip2>0</slip2>
              </ode>
              <torsional>
                <coefficient>1</coefficient>
                <patch_radius>0</patch_radius>
                <surface_radius>0</surface_radius>
                <use_patch_radius>1</use_patch_radius>
                <ode>
                  <slip>0</slip>
                </ode>
              </torsional>
            </friction>
            <bounce>
              <restitution_coefficient>0</restitution_coefficient>
              <threshold>1e+06</threshold>
            </bounce>
            <contact>
              <collide_without_contact>0</collide_without_contact>
              <collide_without_contact_bitmask>1</collide_without_contact_bitmask>
              <collide_bitmask>1</collide_bitmask>
              <ode>
                <soft_cfm>0</soft_cfm>
                <soft_erp>0.2</soft_erp>
                <kp>1e+13</kp>
                <kd>1</kd>
                <max_vel>0.01</max_vel>
                <min_depth>0</min_depth>
              </ode>
              <bullet>
                <split_impulse>1</split_impulse>
                <split_impulse_penetration_threshold>-0.01</split_impulse_penetration_threshold>
                <soft_cfm>0</soft_cfm>
                <soft_erp>0.2</soft_erp>
                <kp>1e+13</kp>
                <kd>1</kd>
              </bullet>
            </contact>
          </surface>
        </collision>
      </link>
      <static>0</static>
      <allow_auto_disable>1</allow_auto_disable>
      <pose frame=''>-3.64155 3.54573 0 0 -0 0</pose>
    </model>
  </world>
</sdf>
